Workbook

Sheet PETUNJUK
A1: LAPORAN KEGIATAN
A2: PROGRAM KESEHATAN IBU
A4: Tahun | C4: 2026
A5: Puskesmas | C5: PECANGAAN | D5: *wajib diisi
A6: Kabupaten | C6: JEPARA
F7: PETUNJUK PENGISIAN
A8: No. | B8: PUSKESMAS | C8: Nama Bidan | F8: 1. | G8: Isilah terlebih dahulu Puskesmas Saudara
A9: 1 | B9: Pecangaan Kulon | C9: Atikuswatun Khasanah, Amd.Keb | F9: 2. | G9: Isi nama Desa dan Bidan Desa di wilayah Puskesmas
A10: 2 | B10: Rengging | C10: Laily Jana Zamana | F10: 3. | G10: Pengisian data hanya pada kolom yang kosong
A11: 3 | B11: Troso | C11: Lazwarni Delfitasari | F11: 4. | G11: Kepala Tabel / nama kolom tidak perlu dirubah
A12: 4 | B12: Ngeling | C12: Chusnul Khotimah, Amd.Keb | F12: 5. | G12: Isi Tabel / Data pada Lampiran 1 sampai 8
A13: 5 | B13: Lebuawu | C13: Ari Susilowati, Amd.Keb | F13: 6. | G13: Isi Tabel / Data pada Lampiran 1 sampai 9 (Bagi Puskesmas PONED)
A14: 6 | B14: Pulodarat | C14: Istikharoh, Amd.Keb | F14: 7. | G14: Rekapitulasi akan dihitung secara otomatis
A15: 7 | B15: Karangrandu | C15: Sri Astuti, Amd.Keb | F15: 8. | G15: Untuk Cetak Laporan : Blok area yg akan di Print kemudian set print area
A16: 8 | B16: Kaliombo | C16: Rohanna Kudus, Amd.Keb
A17: 9 | B17: Gemulung | C17: Marlinda Silviani, Amd.Keb
A18: 10 | B18: Pecangaan Wetan | C18: Nurul Laiyah, Amd.Keb
A19: 11 | B19: Krasak | C19: Tri Romandhiyah, Amd.Keb
A20: 12 | B20: Gerdu | C20: Septiyani Solichah, Amd.Keb
A21: 13
A22: 14
A23: 15
A24: 16
A25: 17
A26: 18
A27: 19
A28: 20
A29: 21
A30: 22

Sheet 1.DATA KIA
A1: DATA ANC, PERSALINAN, NIFAS
A3: PUSKESMAS : | C3: =PETUNJUK!C5 -> PECANGAAN
A4: BULAN : | C4: JANUARI
A6: NO | B6: DESA | C6: SASARAN | F6: K 1 | G6: Ibu Hamil dengan 4T | H6: K1 oleh dokter | I6: K1 USG oleh dokter | J6: K 4 | K6: K5 oleh dokter | L6: K5 USG oleh dokter | M6: K 6 | N6: K 8 | O6: ANC standar 12 T | P6: TM 1 Riil | Q6: Status T Bumil | W6: Fe. 1 | X6: Fe. 3 | Y6: Deteksi Risti | AA6: Rujukan Kasus Risti Maternal | AB6: PERSALINAN | AF6: Komplikasi Maternal Ditangani (PK) | AG6: NEONATUS | AH6: VIT.A NIFAS | AI6: Kunjungan Nifas
C7: BUMIL | D7: BULIN | E7: KOMPLIKASI | Q7: TT 1 | R7: TT 2 | S7: TT 3 | T7: TT 4 | U7: TT 5 | V7: T2 + | Y7: Nakes | Z7: Masyarakat | AB7: DITOLONG NAKES | AE7: DI TOLONG NON NAKES | AI7: KF 1 | AJ7: KF 2 | AK7: KF 3 | AL7: KF 4
AB8: PN | AC8: PN Di Fasyankes | AD8: PN Di Non Fasyankes
A9: 1 | B9: =PETUNJUK!B9 -> Pecangaan Kulon | C9: 101.2 | D9: 96.6 | E9: =C9*20% -> 20.24 | F9: 7 | G9: 1 | H9: 7 | I9: 7 | J9: 6 | K9: 7 | L9: 7 | M9: 8 | N9: 10 | O9: 8 | P9: 3 | T9: 5 | U9: 2 | V9: =SUM(R9:U9) -> 7 | W9: =F9 -> 7 | X9: =J9 -> 6 | Y9: 3 | Z9: 2 | AA9: =Y9 -> 3 | AB9: 10 | AC9: =AB9 -> 10 | AF9: ='3.Komplikasi'!AJ7 -> 1 | AG9: =AB9 -> 10 | AH9: =AB9 -> 10 | AI9: =AB9 -> 10 | AJ9: =AB9 -> 10 | AK9: =AB9 -> 10 | AL9: =AB9 -> 10
A10: 2 | B10: =PETUNJUK!B10 -> Rengging | C10: 111.1 | D10: 106.05 | E10: =C10*20% -> 22.22 | F10: 23 | G10: 3 | H10: 22 | I10: 22 | J10: 9 | K10: 9 | L10: 9 | M10: 20 | N10: 18 | O10: 20 | P10: 20 | S10: 9 | T10: 5 | U10: 4 | V10: =SUM(R10:U10) -> 18 | W10: =F10 -> 23 | X10: =J10 -> 9 | Y10: 3 | Z10: 2 | AA10: =Y10 -> 3 | AB10: 14 | AC10: =AB10 -> 14 | AF10: ='3.Komplikasi'!AJ8 -> 2 | AG10: =AB10 -> 14 | AH10: =AB10 -> 14 | AI10: =AB10 -> 14 | AJ10: =AB10 -> 14 | AK10: =AB10 -> 14 | AL10: =AB10 -> 14
A11: 3 | B11: =PETUNJUK!B11 -> Troso | C11: 205.7 | D11: 196.35 | E11: =C11*20% -> 41.14 | F11: 18 | G11: 4 | H11: 18 | I11: 18 | J11: 15 | K11: 20 | L11: 18 | M11: 19 | N11: 20 | O11: 19 | P11: 15 | S11: 12 | T11: 6 | U11: 5 | V11: =SUM(R11:U11) -> 23 | W11: =F11 -> 18 | X11: =J11 -> 15 | Y11: 3 | Z11: 2 | AA11: =Y11 -> 3 | AB11: 17 | AC11: =AB11 -> 17 | AF11: ='3.Komplikasi'!AJ9 -> 4 | AG11: =AB11 -> 17 | AH11: =AB11 -> 17 | AI11: =AB11 -> 17 | AJ11: =AB11 -> 17 | AK11: =AB11 -> 17 | AL11: =AB11 -> 17
A12: 4 | B12: =PETUNJUK!B12 -> Ngeling | C12: 95.7 | D12: 91.35 | E12: =C12*20% -> 19.14 | F12: 7 | G12: 1 | H12: 7 | I12: 7 | J12: 8 | K12: 4 | L12: 4 | M12: 6 | N12: 9 | O12: 6 | P12: 3 | T12: 3 | U12: 4 | V12: =SUM(R12:U12) -> 7 | W12: =F12 -> 7 | X12: =J12 -> 8 | Y12: 2 | Z12: 2 | AA12: =Y12 -> 2 | AB12: 9 | AC12: =AB12 -> 9 | AF12: ='3.Komplikasi'!AJ10 -> 3 | AG12: =AB12 -> 9 | AH12: =AB12 -> 9 | AI12: =AB12 -> 9 | AJ12: =AB12 -> 9 | AK12: =AB12 -> 9 | AL12: =AB12 -> 9
A13: 5 | B13: =PETUNJUK!B13 -> Lebuawu | C13: 85.8 | D13: 81.9 | E13: =C13*20% -> 17.16 | F13: 9 | G13: 2 | H13: 9 | I13: 9 | J13: 7 | K13: 6 | L13: 6 | M13: 6 | N13: 5 | O13: 6 | P13: 4 | T13: 6 | U13: 3 | V13: =SUM(R13:U13) -> 9 | W13: =F13 -> 9 | X13: =J13 -> 7 | Y13: 1 | Z13: 1 | AA13: =Y13 -> 1 | AB13: 7 | AC13: =AB13 -> 7 | AF13: ='3.Komplikasi'!AJ11 -> 0 | AG13: =AB13 -> 7 | AH13: =AB13 -> 7 | AI13: =AB13 -> 7 | AJ13: =AB13 -> 7 | AK13: =AB13 -> 7 | AL13: =AB13 -> 7
A14: 6 | B14: =PETUNJUK!B14 -> Pulodarat | C14: 82.5 | D14: 78.75 | E14: =C14*20% -> 16.5 | F14: 5 | G14: 0 | H14: 5 | I14: 5 | J14: 6 | K14: 6 | L14: 6 | M14: 6 | N14: 5 | O14: 5 | P14: 5 | T14: 3 | U14: 2 | V14: =SUM(R14:U14) -> 5 | W14: =F14 -> 5 | X14: =J14 -> 6 | Y14: 0 | Z14: 0 | AA14: =Y14 -> 0 | AB14: 7 | AC14: =AB14 -> 7 | AF14: ='3.Komplikasi'!AJ12 -> 0 | AG14: =AB14 -> 7 | AH14: =AB14 -> 7 | AI14: =AB14 -> 7 | AJ14: =AB14 -> 7 | AK14: =AB14 -> 7 | AL14: =AB14 -> 7
A15: 7 | B15: =PETUNJUK!B15 -> Karangrandu | C15: 93.5 | D15: 89.25 | E15: =C15*20% -> 18.7 | F15: 7 | G15: 2 | H15: 7 | I15: 7 | J15: 5 | K15: 4 | L15: 4 | M15: 5 | N15: 5 | O15: 5 | P15: 8 | T15: 2 | U15: 5 | V15: =SUM(R15:U15) -> 7 | W15: =F15 -> 7 | X15: =J15 -> 5 | Y15: 3 | Z15: 1 | AA15: =Y15 -> 3 | AB15: 5 | AC15: =AB15 -> 5 | AF15: ='3.Komplikasi'!AJ13 -> 0 | AG15: =AB15 -> 5 | AH15: =AB15 -> 5 | AI15: =AB15 -> 5 | AJ15: =AB15 -> 5 | AK15: =AB15 -> 5 | AL15: =AB15 -> 5
A16: 8 | B16: =PETUNJUK!B16 -> Kaliombo | C16: 46.2 | D16: 44.1 | E16: =C16*20% -> 9.24 | F16: 1 | G16: 1 | H16: 1 | I16: 1 | J16: 1 | K16: 1 | L16: 1 | M16: 1 | N16: 1 | O16: 1 | P16: 2 | T16: 0 | U16: 1 | V16: =SUM(R16:U16) -> 1 | W16: =F16 -> 1 | X16: =J16 -> 1 | Y16: 1 | Z16: 0 | AA16: =Y16 -> 1 | AB16: 1 | AC16: =AB16 -> 1 | AF16: ='3.Komplikasi'!AJ14 -> 0 | AG16: =AB16 -> 1 | AH16: =AB16 -> 1 | AI16: =AB16 -> 1 | AJ16: =AB16 -> 1 | AK16: =AB16 -> 1 | AL16: =AB16 -> 1
A17: 9 | B17: =PETUNJUK!B17 -> Gemulung | C17: 53.9 | D17: 51.45 | E17: =C17*20% -> 10.78 | F17: 4 | G17: 1 | H17: 4 | I17: 4 | J17: 5 | K17: 5 | L17: 5 | M17: 5 | N17: 2 | O17: 5 | P17: 4 | T17: 1 | U17: 3 | V17: =SUM(R17:U17) -> 4 | W17: =F17 -> 4 | X17: =J17 -> 5 | Y17: 0 | Z17: 0 | AA17: =Y17 -> 0 | AB17: 3 | AC17: =AB17 -> 3 | AF17: ='3.Komplikasi'!AJ15 -> 1 | AG17: =AB17 -> 3 | AH17: =AB17 -> 3 | AI17: =AB17 -> 3 | AJ17: =AB17 -> 3 | AK17: =AB17 -> 3 | AL17: =AB17 -> 3
A18: 10 | B18: =PETUNJUK!B18 -> Pecangaan Wetan | C18: 50.6 | D18: 48.3 | E18: =C18*20% -> 10.12 | F18: 4 | G18: 0 | H18: 4 | I18: 4 | J18: 3 | K18: 3 | L18: 3 | M18: 2 | N18: 2 | O18: 2 | P18: 4 | T18: 0 | U18: 4 | V18: =SUM(R18:U18) -> 4 | W18: =F18 -> 4 | X18: =J18 -> 3 | Y18: 1 | Z18: 0 | AA18: =Y18 -> 1 | AB18: 7 | AC18: =AB18 -> 7 | AF18: ='3.Komplikasi'!AJ16 -> 0 | AG18: =AB18 -> 7 | AH18: =AB18 -> 7 | AI18: =AB18 -> 7 | AJ18: =AB18 -> 7 | AK18: =AB18 -> 7 | AL18: =AB18 -> 7
A19: 11 | B19: =PETUNJUK!B19 -> Krasak | C19: 117.7 | D19: 112.35 | E19: =C19*20% -> 23.54 | F19: 15 | G19: 2 | H19: 5 | I19: 5 | J19: 4 | K19: 10 | L19: 10 | M19: 8 | N19: 8 | O19: 10 | P19: 14 | T19: 5 | U19: 10 | V19: =SUM(R19:U19) -> 15 | W19: =F19 -> 15 | X19: =J19 -> 4 | Y19: 1 | Z19: 1 | AA19: =Y19 -> 1 | AB19: 8 | AC19: =AB19 -> 8 | AF19: ='3.Komplikasi'!AJ17 -> 4 | AG19: =AB19 -> 8 | AH19: =AB19 -> 8 | AI19: =AB19 -> 8 | AJ19: =AB19 -> 8 | AK19: =AB19 -> 8 | AL19: =AB19 -> 8
A20: 12 | B20: =PETUNJUK!B20 -> Gerdu | C20: 23.1 | D20: 22.05 | E20: =C20*20% -> 4.62 | F20: 1 | G20: 0 | H20: 1 | I20: 1 | J20: 3 | K20: 3 | L20: 3 | M20: 2 | N20: 0 | O20: 2 | P20: 2 | T20: 0 | U20: 1 | V20: =SUM(R20:U20) -> 1 | W20: =F20 -> 1 | X20: =J20 -> 3 | Y20: 0 | Z20: 0 | AA20: =Y20 -> 0 | AB20: 2 | AC20: =AB20 -> 2 | AF20: ='3.Komplikasi'!AJ18 -> 1 | AG20: =AB20 -> 2 | AH20: =AB20 -> 2 | AI20: =AB20 -> 2 | AJ20: =AB20 -> 2 | AK20: =AB20 -> 2 | AL20: =AB20 -> 2
A21: 13 | B21: =PETUNJUK!B21 -> 0 | E21: =C21*20% -> 0
A22: 14 | B22: =PETUNJUK!B22 -> 0 | E22: =C22*20% -> 0
A23: 15 | B23: =PETUNJUK!B23 -> 0 | E23: =C23*20% -> 0
A24: 16 | B24: =PETUNJUK!B24 -> 0 | E24: =C24*20% -> 0
A25: 17 | B25: =PETUNJUK!B25 -> 0 | E25: =C25*20% -> 0
A26: 18 | B26: =PETUNJUK!B26 -> 0 | E26: =C26*20% -> 0
A27: 19 | B27: =PETUNJUK!B27 -> 0 | E27: =C27*20% -> 0
A28: 20 | B28: =PETUNJUK!B28 -> 0 | E28: =C28*20% -> 0
A29: 21 | B29: =PETUNJUK!B29 -> 0 | E29: =C29*20% -> 0
A30: 22 | B30: =PETUNJUK!B30 -> 0 | E30: =C30*20% -> 0
A31: JUMLAH | C31: =SUM(C9:C30) -> 1067 | D31: =SUM(D9:D30) -> 1018.5 | E31: =20%*C31 -> 213.4 | F31: =SUM(F9:F30) -> 101 | G31: =SUM(G9:G30) -> 17 | H31: =SUM(H9:H30) -> 90 | I31: =SUM(I9:I30) -> 90 | J31: =SUM(J9:J30) -> 72 | K31: =SUM(K9:K30) -> 78 | L31: =SUM(L9:L30) -> 76 | M31: =SUM(M9:M30) -> 88 | ... AL31: =SUM(AL9:AL30) -> 90
A35: DATA ANC, PERSALINAN, NIFAS
A37: PUSKESMAS : | C37: =PETUNJUK!C5 -> PECANGAAN
A38: BULAN : | C38: PEBRUARI
A40: NO | B40: DESA | C40: SASARAN | F40: K 1 | G40: Ibu Hamil dengan 4T | H40: K1 oleh dokter | I40: K1 USG oleh dokter | J40: K 4 | K40: K5 oleh dokter | L40: K5 USG oleh dokter | M40: K 6 | N40: K 8 | O40: ANC standar 12 T | P40: TM 1 Riil | Q40: Status T Bumil | W40: Fe. 1 | X40: Fe. 3 | Y40: Deteksi Risti | AA40: Rujukan Kasus Risti Maternal | AB40: PERSALINAN | AF40: Komplikasi Maternal Ditangani (PK) | AG40: NEONATUS | AH40: VIT.A NIFAS | AI40: Kunjungan Nifas
C41: BUMIL | D41: BULIN | E41: KOMPLIKASI | Q41: TT 1 | R41: TT 2 | S41: TT 3 | T41: TT 4 | U41: TT 5 | V41: T2 + | Y41: Nakes | Z41: Masyarakat | AB41: DITOLONG NAKES | AE41: DI TOLONG NON NAKES | AI41: KF 1 | AJ41: KF 2 | AK41: KF 3 | AL41: KF 4
AB42: PN | AC42: PN Di Fasyankes | AD42: PN Di Non Fasyankes
A43: 1 | B43: =PETUNJUK!B9 -> Pecangaan Kulon | C43: =C9 -> 101.2 | D43: =D9 -> 96.6 | E43: =E9 -> 20.24 | F43: 8 | G43: 0 | H43: 8 | I43: 8 | J43: 7 | K43: 6 | L43: 6 | M43: 8 | N43: 8 | O43: 8 | P43: 5 | T43: 5 | U43: 3 | V43: =SUM(R43:U43) -> 8 | W43: =F43 -> 8 | X43: =J43 -> 7 | Y43: 3 | Z43: 1 | AA43: =Y43 -> 3 | AB43: 7 | AC43: =AB43 -> 7 | AF43: ='3.Komplikasi'!AJ42 -> 4 | AG43: =AB43 -> 7 | AH43: =AB43 -> 7 | AI43: =AB43 -> 7 | AJ43: =AB43 -> 7 | AK43: =AB43 -> 7 | AL43: =AB43 -> 7
A44: 2 | B44: =PETUNJUK!B10 -> Rengging | C44: =C10 -> 111.1 | D44: =D10 -> 106.05 | E44: =E10 -> 22.22 | F44: 6 | G44: 2 | H44: 6 | I44: 6 | J44: 4 | K44: 6 | L44: 6 | M44: 6 | N44: 3 | O44: 6 | P44: 5 | S44: 4 | T44: 1 | U44: 1 | V44: =SUM(R44:U44) -> 6 | W44: =F44 -> 6 | X44: =J44 -> 4 | Y44: 2 | Z44: 1 | AA44: =Y44 -> 2 | AB44: 4 | AC44: =AB44 -> 4 | AF44: ='3.Komplikasi'!AJ43 -> 0 | AG44: =AB44 -> 4 | AH44: =AB44 -> 4 | AI44: =AB44 -> 4 | AJ44: =AB44 -> 4 | AK44: =AB44 -> 4 | AL44: =AB44 -> 4
A45: 3 | B45: =PETUNJUK!B11 -> Troso | C45: =C11 -> 205.7 | D45: =D11 -> 196.35 | E45: =E11 -> 41.14 | F45: 17 | G45: 2 | H45: 17 | I45: 17 | J45: 13 | K45: 18 | L45: 18 | M45: 20 | N45: 20 | O45: 20 | P45: 16 | S45: 6 | T45: 8 | U45: 3 | V45: =SUM(R45:U45) -> 17 | W45: =F45 -> 17 | X45: =J45 -> 13 | Y45: 4 | Z45: 5 | AA45: =Y45 -> 4 | AB45: 17 | AC45: =AB45 -> 17 | AF45: ='3.Komplikasi'!AJ44 -> 2 | AG45: =AB45 -> 17 | AH45: =AB45 -> 17 | AI45: =AB45 -> 17 | AJ45: =AB45 -> 17 | AK45: =AB45 -> 17 | AL45: =AB45 -> 17
A46: 4 | B46: =PETUNJUK!B12 -> Ngeling | C46: =C12 -> 95.7 | D46: =D12 -> 91.35 | E46: =E12 -> 19.14 | F46: 4 | G46: 0 | H46: 9 | I46: 9 | J46: 6 | K46: 8 | L46: 8 | M46: 5 | N46: 6 | O46: 5 | P46: 2 | T46: 2 | U46: 2 | V46: =SUM(R46:U46) -> 4 | W46: =F46 -> 4 | X46: =J46 -> 6 | Y46: 3 | Z46: 3 | AA46: =Y46 -> 3 | AB46: 7 | AC46: =AB46 -> 7 | AF46: ='3.Komplikasi'!AJ45 -> 3 | AG46: =AB46 -> 7 | AH46: =AB46 -> 7 | AI46: =AB46 -> 7 | AJ46: =AB46 -> 7 | AK46: =AB46 -> 7 | AL46: =AB46 -> 7
A47: 5 | B47: =PETUNJUK!B13 -> Lebuawu | C47: =C13 -> 85.8 | D47: =D13 -> 81.9 | E47: =E13 -> 17.16 | F47: 11 | G47: 0 | H47: 11 | I47: 11 | J47: 5 | K47: 4 | L47: 4 | M47: 4 | N47: 4 | O47: 4 | P47: 9 | T47: 1 | U47: 10 | V47: =SUM(R47:U47) -> 11 | W47: =F47 -> 11 | X47: =J47 -> 5 | Y47: 2 | Z47: 2 | AA47: =Y47 -> 2 | AB47: 4 | AC47: =AB47 -> 4 | AF47: ='3.Komplikasi'!AJ46 -> 0 | AG47: =AB47 -> 4 | AH47: =AB47 -> 4 | AI47: =AB47 -> 4 | AJ47: =AB47 -> 4 | AK47: =AB47 -> 4 | AL47: =AB47 -> 4
...

Sheet 2.PWS
A1: LAPORAN PWS KIA
B2: PUSKESMAS : | C2: =PETUNJUK!C5 -> PECANGAAN
B3: BULAN : | C3: ='1.DATA KIA'!C4 -> JANUARI
A5: NO | B5: DESA | C5: SASARAN | F5: K 1 | K5: K 4 | P5: K 6 | U5: DETEKSI RESIKO TINGGI | AE5: BUMIL | AM5: NEONATUS | AR5: PERSALINAN OLEH NAKES | AW5: KOMPLIKASI DITANGANI
C6: BUMIL | D6: BULIN | E6: BAYI | F6: BLN LALU | G6: BLN INI | H6: KUM | J6: RANGKING | K6: BLN LALU | L6: BLN INI | M6: KUM | O6: RANGKING | P6: BLN LALU | Q6: BLN INI | R6: KUM | T6: RANGKING | U6: OLEH NAKES | Z6: OLEH MASYARAKAT | AE6: ANEMIA | AI6: KEK | AM6: BLN. LALU | AN6: BLN. INI | AO6: ABS | AP6: % | AQ6: RANGKING | AR6: BLN. LALU | AS6: BLN. INI | AT6: ABS | AU6: % | AV6: RANGKING | AW6: BLN. LALU | AX6: BLN. INI | AY6: ABS | AZ6: % | BA6: RANGKING
H7: ABS | I7: % | M7: ABS | N7: % | R7: ABS | S7: % | U7: BLN LALU | V7: BLN INI | W7: KUM | Y7: RANGKING | Z7: BLN LALU | AA7: BLN INI | AB7: KUM | AD7: RANGKING | AE7: < 11 MG | AI7: <23,5
W8: ABS | X8: % | AB8: ABS | AC8: % | AE8: BLN LALU | AF8: BLN INI | AG8: ABS | AH8: % | AI8: BLN LALU | AJ8: BLN INI | AK8: ABS | AL8: %
A9: 1 | B9: =PETUNJUK!B9 -> Pecangaan Kulon | C9: ='1.DATA KIA'!C9 -> 101.2 | D9: ='1.DATA KIA'!D9 -> 96.6 | F9: 0 | G9: ='1.DATA KIA'!F9 -> 7 | H9: =G9+F9 -> 7 | I9: =H9/C9*100 -> 6.916996 | K9: 0 | L9: ='1.DATA KIA'!J9 -> 6 | M9: =L9+K9 -> 6 | N9: =M9/D9*100 -> 6.2111801 | P9: 0 | Q9: ='1.DATA KIA'!M9 -> 8 | R9: =Q9+P9 -> 8 | S9: =R9/D9*100 -> 8.2815735 | U9: 0 | V9: ='1.DATA KIA'!Y9 -> 3 | W9: =V9+U9 -> 3 | X9: =W9/(20%*C9)*100 -> 14.822134 | Z9: 0 | AA9: ='1.DATA KIA'!Z9 -> 2 | AB9: =AA9+Z9 -> 2 | AC9: =AB9/(20%*C9)*100 -> 9.8814229 | AE9: 0 | AF9: ='8.ANCTEPADU'!D11+'8.ANCTEPADU'!E11 -> 2 | AG9: =AF9+AE9 -> 2 | AH9: =AG9/C9*100 -> 1.9762846 | AI9: 0 | AJ9: ='8.ANCTEPADU'!J11 -> 0 | AK9: =AJ9+AI9 -> 0 | AL9: =AK9/C9*100 -> 0 | AM9: 0 | AN9: ='1.DATA KIA'!AG9 -> 10 | AO9: =AN9+AM9 -> 10 | AP9: =AO9/E9*100 -> #DIV/0! | AR9: 0 | AS9: ='1.DATA KIA'!AB9 -> 10 | AT9: =AS9+AR9 -> 10 | AU9: =AT9/D9*100 -> 10.351967 | AW9: 0 | AX9: ='1.DATA KIA'!AF9 -> 1 | AY9: =AX9+AW9 -> 1 | AZ9: =AY9/(20%*C9)*100 -> 4.9407115
A10: 2 | B10: =PETUNJUK!B10 -> Rengging | C10: ='1.DATA KIA'!C10 -> 111.1 | D10: ='1.DATA KIA'!D10 -> 106.05 | F10: 0 | G10: ='1.DATA KIA'!F10 -> 23 | H10: =G10+F10 -> 23 | I10: =H10/C10*100 -> 20.70207 | K10: 0 | L10: ='1.DATA KIA'!J10 -> 9 | M10: =L10+K10 -> 9 | N10: =M10/D10*100 -> 8.4865629 | P10: 0 | Q10: ='1.DATA KIA'!M10 -> 20 | R10: =Q10+P10 -> 20 | S10: =R10/D10*100 -> 18.859029 | U10: 0 | V10: ='1.DATA KIA'!Y10 -> 3 | W10: =V10+U10 -> 3 | X10: =W10/(20%*C10)*100 -> 13.50135 | Z10: 0 | AA10: ='1.DATA KIA'!Z10 -> 2 | AB10: =AA10+Z10 -> 2 | AC10: =AB10/(20%*C10)*100 -> 9.0009001 | AE10: 0 | AF10: ='8.ANCTEPADU'!D12+'8.ANCTEPADU'!E12 -> 2 | AG10: =AF10+AE10 -> 2 | AH10: =AG10/C10*100 -> 1.80018 | AI10: 0 | AJ10: ='8.ANCTEPADU'!J12 -> 3 | AK10: =AJ10+AI10 -> 3 | AL10: =AK10/C10*100 -> 2.70027 | AM10: 0 | AN10: ='1.DATA KIA'!AG10 -> 14 | AO10: =AN10+AM10 -> 14 | AP10: =AO10/E10*100 -> #DIV/0! | AR10: 0 | AS10: ='1.DATA KIA'!AB10 -> 14 | AT10: =AS10+AR10 -> 14 | AU10: =AT10/D10*100 -> 13.20132 | AW10: 0 | AX10: ='1.DATA KIA'!AF10 -> 2 | AY10: =AX10+AW10 -> 2 | AZ10: =AY10/(20%*C10)*100 -> 9.0009001
A11: 3 | B11: =PETUNJUK!B11 -> Troso | C11: ='1.DATA KIA'!C11 -> 205.7 | D11: ='1.DATA KIA'!D11 -> 196.35 | F11: 0 | G11: ='1.DATA KIA'!F11 -> 18 | H11: =G11+F11 -> 18 | I11: =H11/C11*100 -> 8.7506077 | K11: 0 | L11: ='1.DATA KIA'!J11 -> 15 | M11: =L11+K11 -> 15 | N11: =M11/D11*100 -> 7.6394194 | P11: 0 | Q11: ='1.DATA KIA'!M11 -> 19 | R11: =Q11+P11 -> 19 | S11: =R11/D11*100 -> 9.6765979 | U11: 0 | V11: ='1.DATA KIA'!Y11 -> 3 | W11: =V11+U11 -> 3 | X11: =W11/(20%*C11)*100 -> 7.2921731 | Z11: 0 | AA11: ='1.DATA KIA'!Z11 -> 2 | AB11: =AA11+Z11 -> 2 | AC11: =AB11/(20%*C11)*100 -> 4.8614487 | AE11: 0 | AF11: ='8.ANCTEPADU'!D13+'8.ANCTEPADU'!E13 -> 1 | AG11: =AF11+AE11 -> 1 | AH11: =AG11/C11*100 -> 0.48614487 | AI11: 0 | AJ11: ='8.ANCTEPADU'!J13 -> 3 | AK11: =AJ11+AI11 -> 3 | AL11: =AK11/C11*100 -> 1.4584346 | AM11: 0 | AN11: ='1.DATA KIA'!AG11 -> 17 | AO11: =AN11+AM11 -> 17 | AP11: =AO11/E11*100 -> #DIV/0! | AR11: 0 | AS11: ='1.DATA KIA'!AB11 -> 17 | AT11: =AS11+AR11 -> 17 | AU11: =AT11/D11*100 -> 8.6580087 | AW11: 0 | AX11: ='1.DATA KIA'!AF11 -> 4 | AY11: =AX11+AW11 -> 4 | AZ11: =AY11/(20%*C11)*100 -> 9.7228974
A12: 4 | B12: =PETUNJUK!B12 -> Ngeling | C12: ='1.DATA KIA'!C12 -> 95.7 | D12: ='1.DATA KIA'!D12 -> 91.35 | F12: 0 | G12: ='1.DATA KIA'!F12 -> 7 | H12: =G12+F12 -> 7 | I12: =H12/C12*100 -> 7.3145246 | K12: 0 | L12: ='1.DATA KIA'!J12 -> 8 | M12: =L12+K12 -> 8 | N12: =M12/D12*100 -> 8.757526 | P12: 0 | Q12: ='1.DATA KIA'!M12 -> 6 | R12: =Q12+P12 -> 6 | S12: =R12/D12*100 -> 6.5681445 | U12: 0 | V12: ='1.DATA KIA'!Y12 -> 2 | W12: =V12+U12 -> 2 | X12: =W12/(20%*C12)*100 -> 10.449321 | Z12: 0 | AA12: ='1.DATA KIA'!Z12 -> 2 | AB12: =AA12+Z12 -> 2 | AC12: =AB12/(20%*C12)*100 -> 10.449321 | AE12: 0 | AF12: ='8.ANCTEPADU'!D14+'8.ANCTEPADU'!E14 -> 0 | AG12: =AF12+AE12 -> 0 | AH12: =AG12/C12*100 -> 0 | AI12: 0 | AJ12: ='8.ANCTEPADU'!J14 -> 2 | AK12: =AJ12+AI12 -> 2 | AL12: =AK12/C12*100 -> 2.0898642 | AM12: 0 | AN12: ='1.DATA KIA'!AG12 -> 9 | AO12: =AN12+AM12 -> 9 | AP12: =AO12/E12*100 -> #DIV/0! | AR12: 0 | AS12: ='1.DATA KIA'!AB12 -> 9 | AT12: =AS12+AR12 -> 9 | AU12: =AT12/D12*100 -> 9.8522167 | AW12: 0 | AX12: ='1.DATA KIA'!AF12 -> 3 | AY12: =AX12+AW12 -> 3 | AZ12: =AY12/(20%*C12)*100 -> 15.673981
A13: 5 | B13: =PETUNJUK!B13 -> Lebuawu | C13: ='1.DATA KIA'!C13 -> 85.8 | D13: ='1.DATA KIA'!D13 -> 81.9 | F13: 0 | G13: ='1.DATA KIA'!F13 -> 9 | H13: =G13+F13 -> 9 | I13: =H13/C13*100 -> 10.48951 | K13: 0 | L13: ='1.DATA KIA'!J13 -> 7 | M13: =L13+K13 -> 7 | N13: =M13/D13*100 -> 8.5470085 | P13: 0 | Q13: ='1.DATA KIA'!M13 -> 6 | R13: =Q13+P13 -> 6 | S13: =R13/D13*100 -> 7.3260073 | U13: 0 | V13: ='1.DATA KIA'!Y13 -> 1 | W13: =V13+U13 -> 1 | X13: =W13/(20%*C13)*100 -> 5.8275058 | Z13: 0 | AA13: ='1.DATA KIA'!Z13 -> 1 | AB13: =AA13+Z13 -> 1 | AC13: =AB13/(20%*C13)*100 -> 5.8275058 | AE13: 0 | AF13: ='8.ANCTEPADU'!D15+'8.ANCTEPADU'!E15 -> 2 | AG13: =AF13+AE13 -> 2 | AH13: =AG13/C13*100 -> 2.3310023 | AI13: 0 | AJ13: ='8.ANCTEPADU'!J15 -> 1 | AK13: =AJ13+AI13 -> 1 | AL13: =AK13/C13*100 -> 1.1655012 | AM13: 0 | AN13: ='1.DATA KIA'!AG13 -> 7 | AO13: =AN13+AM13 -> 7 | AP13: =AO13/E13*100 -> #DIV/0! | AR13: 0 | AS13: ='1.DATA KIA'!AB13 -> 7 | AT13: =AS13+AR13 -> 7 | AU13: =AT13/D13*100 -> 8.5470085 | AW13: 0 | AX13: ='1.DATA KIA'!AF13 -> 0 | AY13: =AX13+AW13 -> 0 | AZ13: =AY13/(20%*C13)*100 -> 0
A14: 6 | B14: =PETUNJUK!B14 -> Pulodarat | C14: ='1.DATA KIA'!C14 -> 82.5 | D14: ='1.DATA KIA'!D14 -> 78.75 | F14: 0 | G14: ='1.DATA KIA'!F14 -> 5 | H14: =G14+F14 -> 5 | I14: =H14/C14*100 -> 6.0606061 | K14: 0 | L14: ='1.DATA KIA'!J14 -> 6 | M14: =L14+K14 -> 6 | N14: =M14/D14*100 -> 7.6190476 | P14: 0 | Q14: ='1.DATA KIA'!M14 -> 6 | R14: =Q14+P14 -> 6 | S14: =R14/D14*100 -> 7.6190476 | U14: 0 | V14: ='1.DATA KIA'!Y14 -> 0 | W14: =V14+U14 -> 0 | X14: =W14/(20%*C14)*100 -> 0 | Z14: 0 | AA14: ='1.DATA KIA'!Z14 -> 0 | AB14: =AA14+Z14 -> 0 | AC14: =AB14/(20%*C14)*100 -> 0 | AE14: 0 | AF14: ='8.ANCTEPADU'!D16+'8.ANCTEPADU'!E16 -> 1 | AG14: =AF14+AE14 -> 1 | AH14: =AG14/C14*100 -> 1.2121212 | AI14: 0 | AJ14: ='8.ANCTEPADU'!J16 -> 0 | AK14: =AJ14+AI14 -> 0 | AL14: =AK14/C14*100 -> 0 | AM14: 0 | AN14: ='1.DATA KIA'!AG14 -> 7 | AO14: =AN14+AM14 -> 7 | AP14: =AO14/E14*100 -> #DIV/0! | AR14: 0 | AS14: ='1.DATA KIA'!AB14 -> 7 | AT14: =AS14+AR14 -> 7 | AU14: =AT14/D14*100 -> 8.8888889 | AW14: 0 | AX14: ='1.DATA KIA'!AF14 -> 0 | AY14: =AX14+AW14 -> 0 | AZ14: =AY14/(20%*C14)*100 -> 0
A15: 7 | B15: =PETUNJUK!B15 -> Karangrandu | C15: ='1.DATA KIA'!C15 -> 93.5 | D15: ='1.DATA KIA'!D15 -> 89.25 | F15: 0 | G15: ='1.DATA KIA'!F15 -> 7 | H15: =G15+F15 -> 7 | I15: =H15/C15*100 -> 7.486631 | K15: 0 | L15: ='1.DATA KIA'!J15 -> 5 | M15: =L15+K15 -> 5 | N15: =M15/D15*100 -> 5.6022409 | P15: 0 | Q15: ='1.DATA KIA'!M15 -> 5 | R15: =Q15+P15 -> 5 | S15: =R15/D15*100 -> 5.6022409 | U15: 0 | V15: ='1.DATA KIA'!Y15 -> 3 | W15: =V15+U15 -> 3 | X15: =W15/(20%*C15)*100 -> 16.042781 | Z15: 0 | AA15: ='1.DATA KIA'!Z15 -> 1 | AB15: =AA15+Z15 -> 1 | AC15: =AB15/(20%*C15)*100 -> 5.3475936 | AE15: 0 | AF15: ='8.ANCTEPADU'!D17+'8.ANCTEPADU'!E17 -> 0 | AG15: =AF15+AE15 -> 0 | AH15: =AG15/C15*100 -> 0 | AI15: 0 | AJ15: ='8.ANCTEPADU'!J17 -> 0 | AK15: =AJ15+AI15 -> 0 | AL15: =AK15/C15*100 -> 0 | AM15: 0 | AN15: ='1.DATA KIA'!AG15 -> 5 | AO15: =AN15+AM15 -> 5 | AP15: =AO15/E15*100 -> #DIV/0! | AR15: 0 | AS15: ='1.DATA KIA'!AB15 -> 5 | AT15: =AS15+AR15 -> 5 | AU15: =AT15/D15*100 -> 5.6022409 | AW15: 0 | AX15: ='1.DATA KIA'!AF15 -> 0 | AY15: =AX15+AW15 -> 0 | AZ15: =AY15/(20%*C15)*100 -> 0
A16: 8 | B16: =PETUNJUK!B16 -> Kaliombo | C16: ='1.DATA KIA'!C16 -> 46.2 | D16: ='1.DATA KIA'!D16 -> 44.1 | F16: 0 | G16: ='1.DATA KIA'!F16 -> 1 | H16: =G16+F16 -> 1 | I16: =H16/C16*100 -> 2.1645022 | K16: 0 | L16: ='1.DATA KIA'!J16 -> 1 | M16: =L16+K16 -> 1 | N16: =M16/D16*100 -> 2.2675737 | P16: 0 | Q16: ='1.DATA KIA'!M16 -> 1 | R16: =Q16+P16 -> 1 | S16: =R16/D16*100 -> 2.2675737 | U16: 0 | V16: ='1.DATA KIA'!Y16 -> 1 | W16: =V16+U16 -> 1 | X16: =W16/(20%*C16)*100 -> 10.822511 | Z16: 0 | AA16: ='1.DATA KIA'!Z16 -> 0 | AB16: =AA16+Z16 -> 0 | AC16: =AB16/(20%*C16)*100 -> 0 | AE16: 0 | AF16: ='8.ANCTEPADU'!D18+'8.ANCTEPADU'!E18 -> 0 | AG16: =AF16+AE16 -> 0 | AH16: =AG16/C16*100 -> 0 | AI16: 0 | AJ16: ='8.ANCTEPADU'!J18 -> 0 | AK16: =AJ16+AI16 -> 0 | AL16: =AK16/C16*100 -> 0 | AM16: 0 | AN16: ='1.DATA KIA'!AG16 -> 1 | AO16: =AN16+AM16 -> 1 | AP16: =AO16/E16*100 -> #DIV/0! | AR16: 0 | AS16: ='1.DATA KIA'!AB16 -> 1 | AT16: =AS16+AR16 -> 1 | AU16: =AT16/D16*100 -> 2.2675737 | AW16: 0 | AX16: ='1.DATA KIA'!AF16 -> 0 | AY16: =AX16+AW16 -> 0 | AZ16: =AY16/(20%*C16)*100 -> 0
A17: 9 | B17: =PETUNJUK!B17 -> Gemulung | C17: ='1.DATA KIA'!C17 -> 53.9 | D17: ='1.DATA KIA'!D17 -> 51.45 | F17: 0 | G17: ='1.DATA KIA'!F17 -> 4 | H17: =G17+F17 -> 4 | I17: =H17/C17*100 -> 7.4211503 | K17: 0 | L17: ='1.DATA KIA'!J17 -> 5 | M17: =L17+K17 -> 5 | N17: =M17/D17*100 -> 9.718173 | P17: 0 | Q17: ='1.DATA KIA'!M17 -> 5 | R17: =Q17+P17 -> 5 | S17: =R17/D17*100 -> 9.718173 | U17: 0 | V17: ='1.DATA KIA'!Y17 -> 0 | W17: =V17+U17 -> 0 | X17: =W17/(20%*C17)*100 -> 0 | Z17: 0 | AA17: ='1.DATA KIA'!Z17 -> 0 | AB17: =AA17+Z17 -> 0 | AC17: =AB17/(20%*C17)*100 -> 0 | AE17: 0 | AF17: ='8.ANCTEPADU'!D19+'8.ANCTEPADU'!E19 -> 2 | AG17: =AF17+AE17 -> 2 | AH17: =AG17/C17*100 -> 3.7105751 | AI17: 0 | AJ17: ='8.ANCTEPADU'!J19 -> 0 | AK17: =AJ17+AI17 -> 0 | AL17: =AK17/C17*100 -> 0 | AM17: 0 | AN17: ='1.DATA KIA'!AG17 -> 3 | AO17: =AN17+AM17 -> 3 | AP17: =AO17/E17*100 -> #DIV/0! | AR17: 0 | AS17: ='1.DATA KIA'!AB17 -> 3 | AT17: =AS17+AR17 -> 3 | AU17: =AT17/D17*100 -> 5.8309038 | AW17: 0 | AX17: ='1.DATA KIA'!AF17 -> 1 | AY17: =AX17+AW17 -> 1 | AZ17: =AY17/(20%*C17)*100 -> 9.2764378
A18: 10 | B18: =PETUNJUK!B18 -> Pecangaan Wetan | C18: ='1.DATA KIA'!C18 -> 50.6 | D18: ='1.DATA KIA'!D18 -> 48.3 | F18: 0 | G18: ='1.DATA KIA'!F18 -> 4 | H18: =G18+F18 -> 4 | I18: =H18/C18*100 -> 7.9051383 | K18: 0 | L18: ='1.DATA KIA'!J18 -> 3 | M18: =L18+K18 -> 3 | N18: =M18/D18*100 -> 6.2111801 | P18: 0 | Q18: ='1.DATA KIA'!M18 -> 2 | R18: =Q18+P18 -> 2 | S18: =R18/D18*100 -> 4.1407867 | U18: 0 | V18: ='1.DATA KIA'!Y18 -> 1 | W18: =V18+U18 -> 1 | X18: =W18/(20%*C18)*100 -> 9.8814229 | Z18: 0 | AA18: ='1.DATA KIA'!Z18 -> 0 | AB18: =AA18+Z18 -> 0 | AC18: =AB18/(20%*C18)*100 -> 0 | AE18: 0 | AF18: ='8.ANCTEPADU'!D20+'8.ANCTEPADU'!E20 -> 0 | AG18: =AF18+AE18 -> 0 | AH18: =AG18/C18*100 -> 0 | AI18: 0 | AJ18: ='8.ANCTEPADU'!J20 -> 2 | AK18: =AJ18+AI18 -> 2 | AL18: =AK18/C18*100 -> 3.9525692 | AM18: 0 | AN18: ='1.DATA KIA'!AG18 -> 7 | AO18: =AN18+AM18 -> 7 | AP18: =AO18/E18*100 -> #DIV/0! | AR18: 0 | AS18: ='1.DATA KIA'!AB18 -> 7 | AT18: =AS18+AR18 -> 7 | AU18: =AT18/D18*100 -> 14.492754 | AW18: 0 | AX18: ='1.DATA KIA'!AF18 -> 0 | AY18: =AX18+AW18 -> 0 | AZ18: =AY18/(20%*C18)*100 -> 0
A19: 11 | B19: =PETUNJUK!B19 -> Krasak | C19: ='1.DATA KIA'!C19 -> 117.7 | D19: ='1.DATA KIA'!D19 -> 112.35 | F19: 0 | G19: ='1.DATA KIA'!F19 -> 15 | H19: =G19+F19 -> 15 | I19: =H19/C19*100 -> 12.744265 | K19: 0 | L19: ='1.DATA KIA'!J19 -> 4 | M19: =L19+K19 -> 4 | N19: =M19/D19*100 -> 3.5603026 | P19: 0 | Q19: ='1.DATA KIA'!M19 -> 8 | R19: =Q19+P19 -> 8 | S19: =R19/D19*100 -> 7.1206053 | U19: 0 | V19: ='1.DATA KIA'!Y19 -> 1 | W19: =V19+U19 -> 1 | X19: =W19/(20%*C19)*100 -> 4.2480884 | Z19: 0 | AA19: ='1.DATA KIA'!Z19 -> 1 | AB19: =AA19+Z19 -> 1 | AC19: =AB19/(20%*C19)*100 -> 4.2480884 | AE19: 0 | AF19: ='8.ANCTEPADU'!D21+'8.ANCTEPADU'!E21 -> 0 | AG19: =AF19+AE19 -> 0 | AH19: =AG19/C19*100 -> 0 | AI19: 0 | AJ19: ='8.ANCTEPADU'!J21 -> 1 | AK19: =AJ19+AI19 -> 1 | AL19: =AK19/C19*100 -> 0.84961767 | AM19: 0 | AN19: ='1.DATA KIA'!AG19 -> 8 | AO19: =AN19+AM19 -> 8 | AP19: =AO19/E19*100 -> #DIV/0! | AR19: 0 | AS19: ='1.DATA KIA'!AB19 -> 8 | AT19: =AS19+AR19 -> 8 | AU19: =AT19/D19*100 -> 7.1206053 | AW19: 0 | AX19: ='1.DATA KIA'!AF19 -> 4 | AY19: =AX19+AW19 -> 4 | AZ19: =AY19/(20%*C19)*100 -> 16.992353
A20: 12 | B20: =PETUNJUK!B20 -> Gerdu | C20: ='1.DATA KIA'!C20 -> 23.1 | D20: ='1.DATA KIA'!D20 -> 22.05 | F20: 0 | G20: ='1.DATA KIA'!F20 -> 1 | H20: =G20+F20 -> 1 | I20: =H20/C20*100 -> 4.3290043 | K20: 0 | L20: ='1.DATA KIA'!J20 -> 3 | M20: =L20+K20 -> 3 | N20: =M20/D20*100 -> 13.605442 | P20: 0 | Q20: ='1.DATA KIA'!M20 -> 2 | R20: =Q20+P20 -> 2 | S20: =R20/D20*100 -> 9.0702948 | U20: 0 | V20: ='1.DATA KIA'!Y20 -> 0 | W20: =V20+U20 -> 0 | X20: =W20/(20%*C20)*100 -> 0 | Z20: 0 | AA20: ='1.DATA KIA'!Z20 -> 0 | AB20: =AA20+Z20 -> 0 | AC20: =AB20/(20%*C20)*100 -> 0 | AE20: 0 | AF20: ='8.ANCTEPADU'!D22+'8.ANCTEPADU'!E22 -> 0 | AG20: =AF20+AE20 -> 0 | AH20: =AG20/C20*100 -> 0 | AI20: 0 | AJ20: ='8.ANCTEPADU'!J22 -> 0 | AK20: =AJ20+AI20 -> 0 | AL20: =AK20/C20*100 -> 0 | AM20: 0 | AN20: ='1.DATA KIA'!AG20 -> 2 | AO20: =AN20+AM20 -> 2 | AP20: =AO20/E20*100 -> #DIV/0! | AR20: 0 | AS20: ='1.DATA KIA'!AB20 -> 2 | AT20: =AS20+AR20 -> 2 | AU20: =AT20/D20*100 -> 9.0702948 | AW20: 0 | AX20: ='1.DATA KIA'!AF20 -> 1 | AY20: =AX20+AW20 -> 1 | AZ20: =AY20/(20%*C20)*100 -> 21.645022
... A30: 22 | B30: =PETUNJUK!B30 -> 0 | C30: ='1.DATA KIA'!C30 -> 0 | D30: ='1.DATA KIA'!D30 -> 0 | F30: 0 | G30: ='1.DATA KIA'!F30 -> 0 | H30: =G30+F30 -> 0 | I30: =H30/C30*100 -> #DIV/0! | K30: 0 | L30: ='1.DATA KIA'!J30 -> 0 | M30: =L30+K30 -> 0 | N30: =M30/D30*100 -> #DIV/0! | P30: 0 | Q30: ='1.DATA KIA'!M30 -> 0 | R30: =Q30+P30 -> 0 | S30: =R30/D30*100 -> #DIV/0! | U30: 0 | V30: ='1.DATA KIA'!Y30 -> 0 | W30: =V30+U30 -> 0 | X30: =W30/(20%*C30)*100 -> #DIV/0! | Z30: 0 | AA30: ='1.DATA KIA'!Z30 -> 0 | AB30: =AA30+Z30 -> 0 | AC30: =AB30/(20%*C30)*100 -> #DIV/0! | AE30: 0 | AF30: ='8.ANCTEPADU'!D32+'8.ANCTEPADU'!E32 -> 0 | AG30: =AF30+AE30 -> 0 | AH30: =AG30/C30*100 -> #DIV/0! | AI30: 0 | AJ30: ='8.ANCTEPADU'!J32 -> 0 | AK30: =AJ30+AI30 -> 0 | AL30: =AK30/C30*100 -> #DIV/0! | AM30: 0 | AN30: ='1.DATA KIA'!AG30 -> 0 | AO30: =AN30+AM30 -> 0 | AP30: =AO30/E30*100 -> #DIV/0! | AR30: 0 | AS30: ='1.DATA KIA'!AB30 -> 0 | AT30: =AS30+AR30 -> 0 | AU30: =AT30/D30*100 -> #DIV/0! | AW30: 0 | AX30: ='1.DATA KIA'!AF30 -> 0 | AY30: =AX30+AW30 -> 0 | AZ30: =AY30/(20%*C30)*100 -> #DIV/0!
B31: JUMLAH | C31: =SUM(C9:C30) -> 1067 | D31: =SUM(D9:D30) -> 1018.5 | E31: =SUM(E9:E30) -> 0 | F31: =SUM(F9:F30) -> 0 | G31: =SUM(G9:G30) -> 101 | H31: =SUM(H9:H30) -> 101 | I31: =H31/C31*100 -> 9.4657919 | J31: =SUM(J9:J30) -> 0 | K31: =SUM(K9:K30) -> 0 | L31: =SUM(L9:L30) -> 72 | M31: =SUM(M9:M30) -> 72 | N31: =M31/D31*100 -> 7.0692194 | O31: =SUM(O9:O30) -> 0 | P31: =SUM(P9:P30) -> 0 | Q31: =SUM(Q9:Q30) -> 88 | R31: =SUM(R9:R30) -> 88 | S31: =R31/D31*100 -> 8.6401571 | T31: =SUM(T9:T30) -> 0 | U31: =SUM(U9:U30) -> 0 | V31: =SUM(V9:V30) -> 18 | W31: =SUM(W9:W30) -> 18 | X31: =W31/(20%*C31)*100 -> 8.4348641 | Y31: =SUM(Y9:Y30) -> 0 | Z31: =SUM(Z9:Z30) -> 0 | AA31: =SUM(AA9:AA30) -> 11 | AB31: =SUM(AB9:AB30) -> 11 | AC31: =AB31/(20%*C31)*100 -> 5.1546392 | AD31: =SUM(AD9:AD30) -> 0 | AE31: =SUM(AE9:AE30) -> 0 | AF31: =SUM(AF9:AF30) -> 10 | AG31: =SUM(AG9:AG30) -> 10 | AH31: =AG31/C31*100 -> 0.93720712 | AI31: =SUM(AI9:AI30) -> 0 | AJ31: =SUM(AJ9:AJ30) -> 12 | AK31: =SUM(AK9:AK30) -> 12 | AL31: =AK31/C31*100 -> 1.1246485 | AM31: =SUM(AM9:AM30) -> 0 | AN31: =SUM(AN9:AN30) -> 90 | AO31: =SUM(AO9:AO30) -> 90 | AP31: =AO31/E31*100 -> #DIV/0! | AQ31: =SUM(AQ9:AQ30) -> 0 | AR31: =SUM(AR9:AR30) -> 0 | AS31: =SUM(AS9:AS30) -> 90 | AT31: =SUM(AT9:AT30) -> 90 | AU31: =AT31/C31*100 -> 8.4348641 | AV31: =SUM(AV9:AV30) -> 0 | AW31: =SUM(AW9:AW30) -> 0 | AX31: =SUM(AX9:AX30) -> 16 | AY31: =SUM(AY9:AY30) -> 16 | AZ31: =AY31/(20%*C31)*100 -> 7.497657
A35: LAPORAN PWS KIA
B36: PUSKESMAS : | C36: =PETUNJUK!C5 -> PECANGAAN
B37: BULAN : | C37: ='1.DATA KIA'!C38 -> PEBRUARI
A39: NO | B39: DESA | C39: SASARAN | F39: K 1 | K39: K 4 | P39: K 6 | U39: DETEKSI RESIKO TINGGI | AE39: BUMIL | AM39: NEONATUS | AR39: PERSALINAN OLEH NAKES | AW39: KOMPLIKASI DITANGANI
C40: BUMIL | D40: BULIN | E40: BAYI | F40: BLN LALU | G40: BLN INI | H40: KUM | J40: RANGKING | K40: BLN LALU | L40: BLN INI | M40: KUM | O40: RANGKING | P40: BLN LALU | Q40: BLN INI | R40: KUM | T40: RANGKING | U40: OLEH NAKES | Z40: OLEH MASYARAKAT | AE40: ANEMIA | AI40: KEK | AM40: BLN. LALU | AN40: BLN. INI | AO40: ABS | AP40: % | AQ40: RANGKING | AR40: BLN. LALU | AS40: BLN. INI | AT40: ABS | AU40: % | AV40: RANGKING | AW40: BLN. LALU | AX40: BLN. INI | AY40: ABS | AZ40: % | BA40: RANGKING
H41: ABS | I41: % | M41: ABS | N41: % | R41: ABS | S41: % | U41: BLN LALU | V41: BLN INI | W41: KUM | Y41: RANGKING | Z41: BLN LALU | AA41: BLN INI | AB41: KUM | AD41: RANGKING | AE41: < 11 MG | AI41: <23,5
W42: ABS | X42: % | AB42: ABS | AC42: % | AE42: BLN LALU | AF42: BLN INI | AG42: ABS | AH42: % | AI42: BLN LALU | AJ42: BLN INI | AK42: ABS | AL42: %
A43: 1 | B43: =PETUNJUK!B9 -> Pecangaan Kulon | C43: ='1.DATA KIA'!C43 -> 101.2 | D43: ='1.DATA KIA'!D43 -> 96.6 | E43: =E9 -> 0 | F43: =H9 -> 7 | G43: ='1.DATA KIA'!F43 -> 8 | H43: =F43+G43 -> 15 | I43: =H43/C43*100 -> 14.822134 | K43: =M9 -> 6 | L43: ='1.DATA KIA'!J43 -> 7 | M43: =K43+L43 -> 13 | N43: =M43/D43*100 -> 13.457557 | P43: =R9 -> 8 | Q43: ='1.DATA KIA'!M43 -> 8 | R43: =P43+Q43 -> 16 | S43: =R43/D43*100 -> 16.563147 | U43: =W9 -> 3 | V43: ='1.DATA KIA'!Y43 -> 3 | W43: =U43+V43 -> 6 | X43: =W43/(20%*C43)*100 -> 29.644269 | Z43: =AB9 -> 2 | AA43: ='1.DATA KIA'!Z43 -> 1 | AB43: =Z43+AA43 -> 3 | AC43: =AB43/(20%*C43)*100 -> 14.822134 | AE43: =AG9 -> 2 | AF43: ='8.ANCTEPADU'!D45+'8.ANCTEPADU'!E45 -> 1 | AG43: =AE43+AF43 -> 3 | AH43: =AG43/C43*100 -> 2.9644269 | AI43: =AK9 -> 0 | AJ43: ='8.ANCTEPADU'!J45 -> 0 | AK43: =AI43+AJ43 -> 0 | AL43: =AK43/C43*100 -> 0 | AM43: =AO9 -> 10 | AN43: ='1.DATA KIA'!AG43 -> 7 | AO43: =AN43+AM43 -> 17 | AP43: =AO43/E43*100 -> #DIV/0! | AR43: =AT9 -> 10 | AS43: ='1.DATA KIA'!AB43 -> 7 | AT43: =AS43+AR43 -> 17 | AU43: =AT43/D43*100 -> 17.598344 | AW43: =AY9 -> 1 | AX43: ='1.DATA KIA'!AF43 -> 4 | AY43: =AW43+AX43 -> 5 | AZ43: =AY43/(20%*C43)*100 -> 24.703557
A44: 2 | B44: =PETUNJUK!B10 -> Rengging | C44: ='1.DATA KIA'!C44 -> 111.1 | D44: ='1.DATA KIA'!D44 -> 106.05 | E44: =E10 -> 0 | F44: =H10 -> 23 | G44: ='1.DATA KIA'!F44 -> 6 | H44: =F44+G44 -> 29 | I44: =H44/C44*100 -> 26.10261 | K44: =M10 -> 9 | L44: ='1.DATA KIA'!J44 -> 4 | M44: =K44+L44 -> 13 | N44: =M44/D44*100 -> 12.258369 | P44: =R10 -> 20 | Q44: ='1.DATA KIA'!M44 -> 6 | R44: =P44+Q44 -> 26 | S44: =R44/D44*100 -> 24.516737 | U44: =W10 -> 3 | V44: ='1.DATA KIA'!Y44 -> 2 | W44: =U44+V44 -> 5 | X44: =W44/(20%*C44)*100 -> 22.50225 | Z44: =AB10 -> 2 | AA44: ='1.DATA KIA'!Z44 -> 1 | AB44: =Z44+AA44 -> 3 | AC44: =AB44/(20%*C44)*100 -> 13.50135 | AE44: =AG10 -> 2 | AF44: ='8.ANCTEPADU'!D46+'8.ANCTEPADU'!E46 -> 1 | AG44: =AE44+AF44 -> 3 | AH44: =AG44/C44*100 -> 2.70027 | AI44: =AK10 -> 3 | AJ44: ='8.ANCTEPADU'!J46 -> 3 | AK44: =AI44+AJ44 -> 6 | AL44: =AK44/C44*100 -> 5.4005401 | AM44: =AO10 -> 14 | AN44: ='1.DATA KIA'!AG44 -> 4 | AO44: =AN44+AM44 -> 18 | AP44: =AO44/E44*100 -> #DIV/0! | AR44: =AT10 -> 14 | AS44: ='1.DATA KIA'!AB44 -> 4 | AT44: =AS44+AR44 -> 18 | AU44: =AT44/D44*100 -> 16.973126 | AW44: =AY10 -> 2 | AX44: ='1.DATA KIA'!AF44 -> 0 | AY44: =AW44+AX44 -> 2 | AZ44: =AY44/(20%*C44)*100 -> 9.0009001
A45: 3 | B45: =PETUNJUK!B11 -> Troso | C45: ='1.DATA KIA'!C45 -> 205.7 | D45: ='1.DATA KIA'!D45 -> 196.35 | E45: =E11 -> 0 | F45: =H11 -> 18 | G45: ='1.DATA KIA'!F45 -> 17 | H45: =F45+G45 -> 35 | I45: =H45/C45*100 -> 17.01507 | K45: =M11 -> 15 | L45: ='1.DATA KIA'!J45 -> 13 | M45: =K45+L45 -> 28 | N45: =M45/D45*100 -> 14.26025 | P45: =R11 -> 19 | Q45: ='1.DATA KIA'!M45 -> 20 | R45: =P45+Q45 -> 39 | S45: =R45/D45*100 -> 19.86249 | U45: =W11 -> 3 | V45: ='1.DATA KIA'!Y45 -> 4 | W45: =U45+V45 -> 7 | X45: =W45/(20%*C45)*100 -> 17.01507 | Z45: =AB11 -> 2 | AA45: ='1.DATA KIA'!Z45 -> 5 | AB45: =Z45+AA45 -> 7 | AC45: =AB45/(20%*C45)*100 -> 17.01507 | AE45: =AG11 -> 1 | AF45: ='8.ANCTEPADU'!D47+'8.ANCTEPADU'!E47 -> 1 | AG45: =AE45+AF45 -> 2 | AH45: =AG45/C45*100 -> 0.97228974 | AI45: =AK11 -> 3 | AJ45: ='8.ANCTEPADU'!J47 -> 3 | AK45: =AI45+AJ45 -> 6 | AL45: =AK45/C45*100 -> 2.9168692 | AM45: =AO11 -> 17 | AN45: ='1.DATA KIA'!AG45 -> 17 | AO45: =AN45+AM45 -> 34 | AP45: =AO45/E45*100 -> #DIV/0! | AR45: =AT11 -> 17 | AS45: ='1.DATA KIA'!AB45 -> 17 | AT45: =AS45+AR45 -> 34 | AU45: =AT45/D45*100 -> 17.316017 | AW45: =AY11 -> 4 | AX45: ='1.DATA KIA'!AF45 -> 2 | AY45: =AW45+AX45 -> 6 | AZ45: =AY45/(20%*C45)*100 -> 14.584346
A46: 4 | B46: =PETUNJUK!B12 -> Ngeling | C46: ='1.DATA KIA'!C46 -> 95.7 | D46: ='1.DATA KIA'!D46 -> 91.35 | E46: =E12 -> 0 | F46: =H12 -> 7 | G46: ='1.DATA KIA'!F46 -> 4 | H46: =F46+G46 -> 11 | I46: =H46/C46*100 -> 11.494253 | K46: =M12 -> 8 | L46: ='1.DATA KIA'!J46 -> 6 | M46: =K46+L46 -> 14 | N46: =M46/D46*100 -> 15.32567 | P46: =R12 -> 6 | Q46: ='1.DATA KIA'!M46 -> 5 | R46: =P46+Q46 -> 11 | S46: =R46/D46*100 -> 12.041598 | U46: =W12 -> 2 | V46: ='1.DATA KIA'!Y46 -> 3 | W46: =U46+V46 -> 5 | X46: =W46/(20%*C46)*100 -> 26.123302 | Z46: =AB12 -> 2 | AA46: ='1.DATA KIA'!Z46 -> 3 | AB46: =Z46+AA46 -> 5 | AC46: =AB46/(20%*C46)*100 -> 26.123302 | AE46: =AG12 -> 0 | AF46: ='8.ANCTEPADU'!D48+'8.ANCTEPADU'!E48 -> 2 | AG46: =AE46+AF46 -> 2 | AH46: =AG46/C46*100 -> 2.0898642 | AI46: =AK12 -> 2 | AJ46: ='8.ANCTEPADU'!J48 -> 2 | AK46: =AI46+AJ46 -> 4 | AL46: =AK46/C46*100 -> 4.1797283 | AM46: =AO12 -> 9 | AN46: ='1.DATA KIA'!AG46 -> 7 | AO46: =AN46+AM46 -> 16 | AP46: =AO46/E46*100 -> #DIV/0! | AR46: =AT12 -> 9 | AS46: ='1.DATA KIA'!AB46 -> 7 | AT46: =AS46+AR46 -> 16 | AU46: =AT46/D46*100 -> 17.515052 | AW46: =AY12 -> 3 | AX46: ='1.DATA KIA'!AF46 -> 3 | AY46: =AW46+AX46 -> 6 | AZ46: =AY46/(20%*C46)*100 -> 31.347962
A47: 5 | B47: =PETUNJUK!B13 -> Lebuawu | C47: ='1.DATA KIA'!C47 -> 85.8 | D47: ='1.DATA KIA'!D47 -> 81.9 | E47: =E13 -> 0 | F47: =H13 -> 9 | G47: ='1.DATA KIA'!F47 -> 11 | H47: =F47+G47 -> 20 | I47: =H47/C47*100 -> 23.310023 | K47: =M13 -> 7 | L47: ='1.DATA KIA'!J47 -> 5 | M47: =K47+L47 -> 12 | N47: =M47/D47*100 -> 14.652015 | P47: =R13 -> 6 | Q47: ='1.DATA KIA'!M47 -> 4 | R47: =P47+Q47 -> 10 | S47: =R47/D47*100 -> 12.210012 | U47: =W13 -> 1 | V47: ='1.DATA KIA'!Y47 -> 2 | W47: =U47+V47 -> 3 | X47: =W47/(20%*C47)*100 -> 17.482517 | Z47: =AB13 -> 1 | AA47: ='1.DATA KIA'!Z47 -> 2 | AB47: =Z47+AA47 -> 3 | AC47: =AB47/(20%*C47)*100 -> 17.482517 | AE47: =AG13 -> 2 | AF47: ='8.ANCTEPADU'!D49+'8.ANCTEPADU'!E49 -> 0 | AG47: =AE47+AF47 -> 2 | AH47: =AG47/C47*100 -> 2.3310023 | AI47: =AK13 -> 1 | AJ47: ='8.ANCTEPADU'!J49 -> 2 | AK47: =AI47+AJ47 -> 3 | AL47: =AK47/C47*100 -> 3.4965035 | AM47: =AO13 -> 7 | AN47: ='1.DATA KIA'!AG47 -> 4 | AO47: =AN47+AM47 -> 11 | AP47: =AO47/E47*100 -> #DIV/0! | AR47: =AT13 -> 7 | AS47: ='1.DATA KIA'!AB47 -> 4 | AT47: =AS47+AR47 -> 11 | AU47: =AT47/D47*100 -> 13.431013 | AW47: =AY13 -> 0 | AX47: ='1.DATA KIA'!AF47 -> 0 | AY47: =AW47+AX47 -> 0 | AZ47: =AY47/(20%*C47)*100 -> 0
A48: 6 | B48: =PETUNJUK!B14 -> Pulodarat | C48: ='1.DATA KIA'!C48 -> 82.5 | D48: ='1.DATA KIA'!D48 -> 78.75 | E48: =E14 -> 0 | F48: =H14 -> 5 | G48: ='1.DATA KIA'!F48 -> 4 | H48: =F48+G48 -> 9 | I48: =H48/C48*100 -> 10.909091 | K48: =M14 -> 6 | L48: ='1.DATA KIA'!J48 -> 5 | M48: =K48+L48 -> 11 | N48: =M48/D48*100 -> 13.968254 | P48: =R14 -> 6 | Q48: ='1.DATA KIA'!M48 -> 5 | R48: =P48+Q48 -> 11 | S48: =R48/D48*100 -> 13.968254 | U48: =W14 -> 0 | V48: ='1.DATA KIA'!Y48 -> 0 | W48: =U48+V48 -> 0 | X48: =W48/(20%*C48)*100 -> 0 | Z48: =AB14 -> 0 | AA48: ='1.DATA KIA'!Z48 -> 0 | AB48: =Z48+AA48 -> 0 | AC48: =AB48/(20%*C48)*100 -> 0 | AE48: =AG14 -> 1 | AF48: ='8.ANCTEPADU'!D50+'8.ANCTEPADU'!E50 -> 1 | AG48: =AE48+AF48 -> 2 | AH48: =AG48/C48*100 -> 2.4242424 | AI48: =AK14 -> 0 | AJ48: ='8.ANCTEPADU'!J50 -> 0 | AK48: =AI48+AJ48 -> 0 | AL48: =AK48/C48*100 -> 0 | AM48: =AO14 -> 7 | AN48: ='1.DATA KIA'!AG48 -> 4 | AO48: =AN48+AM48 -> 11 | AP48: =AO48/E48*100 -> #DIV/0! | AR48: =AT14 -> 7 | AS48: ='1.DATA KIA'!AB48 -> 4 | AT48: =AS48+AR48 -> 11 | AU48: =AT48/D48*100 -> 13.968254 | AW48: =AY14 -> 0 | AX48: ='1.DATA KIA'!AF48 -> 2 | AY48: =AW48+AX48 -> 2 | AZ48: =AY48/(20%*C48)*100 -> 12.121212
A49: 7 | B49: =PETUNJUK!B15 -> Karangrandu | C49: ='1.DATA KIA'!C49 -> 93.5 | D49: ='1.DATA KIA'!D49 -> 89.25 | E49: =E15 -> 0 | F49: =H15 -> 7 | G49: ='1.DATA KIA'!F49 -> 8 | H49: =F49+G49 -> 15 | I49: =H49/C49*100 -> 16.042781 | K49: =M15 -> 5 | L49: ='1.DATA KIA'!J49 -> 8 | M49: =K49+L49 -> 13 | N49: =M49/D49*100 -> 14.565826 | P49: =R15 -> 5 | Q49: ='1.DATA KIA'!M49 -> 7 | R49: =P49+Q49 -> 12 | S49: =R49/D49*100 -> 13.445378 | U49: =W15 -> 3 | V49: ='1.DATA KIA'!Y49 -> 2 | W49: =U49+V49 -> 5 | X49: =W49/(20%*C49)*100 -> 26.737968 | Z49: =AB15 -> 1 | AA49: ='1.DATA KIA'!Z49 -> 1 | AB49: =Z49+AA49 -> 2 | AC49: =AB49/(20%*C49)*100 -> 10.695187 | AE49: =AG15 -> 0 | AF49: ='8.ANCTEPADU'!D51+'8.ANCTEPADU'!E51 -> 1 | AG49: =AE49+AF49 -> 1 | AH49: =AG49/C49*100 -> 1.0695187 | AI49: =AK15 -> 0 | AJ49: ='8.ANCTEPADU'!J51 -> 1 | AK49: =AI49+AJ49 -> 1 | AL49: =AK49/C49*100 -> 1.0695187 | AM49: =AO15 -> 5 | AN49: ='1.DATA KIA'!AG49 -> 4 | AO49: =AN49+AM49 -> 9 | AP49: =AO49/E49*100 -> #DIV/0! | AR49: =AT15 -> 5 | AS49: ='1.DATA KIA'!AB49 -> 5 | AT49: =AS49+AR49 -> 10 | AU49: =AT49/D49*100 -> 11.204482 | AW49: =AY15 -> 0 | AX49: ='1.DATA KIA'!AF49 -> 2 | AY49: =AW49+AX49 -> 2 | AZ49: =AY49/(20%*C49)*100 -> 10.695187
A50: 8 | B50: =PETUNJUK!B16 -> Kaliombo | C50: ='1.DATA KIA'!C50 -> 46.2 | D50: ='1.DATA KIA'!D50 -> 44.1 | E50: =E16 -> 0 | F50: =H16 -> 1 | G50: ='1.DATA KIA'!F50 -> 5 | H50: =F50+G50 -> 6 | I50: =H50/C50*100 -> 12.987013 | K50: =M16 -> 1 | L50: ='1.DATA KIA'!J50 -> 5 | M50: =K50+L50 -> 6 | N50: =M50/D50*100 -> 13.605442 | P50: =R16 -> 1 | Q50: ='1.DATA KIA'!M50 -> 5 | R50: =P50+Q50 -> 6 | S50: =R50/D50*100 -> 13.605442 | U50: =W16 -> 1 | V50: ='1.DATA KIA'!Y50 -> 1 | W50: =U50+V50 -> 2 | X50: =W50/(20%*C50)*100 -> 21.645022 | Z50: =AB16 -> 0 | AA50: ='1.DATA KIA'!Z50 -> 0 | AB50: =Z50+AA50 -> 0 | AC50: =AB50/(20%*C50)*100 -> 0 | AE50: =AG16 -> 0 | AF50: ='8.ANCTEPADU'!D52+'8.ANCTEPADU'!E52 -> 0 | AG50: =AE50+AF50 -> 0 | AH50: =AG50/C50*100 -> 0 | AI50: =AK16 -> 0 | AJ50: ='8.ANCTEPADU'!J52 -> 0 | AK50: =AI50+AJ50 -> 0 | AL50: =AK50/C50*100 -> 0 | AM50: =AO16 -> 1 | AN50: ='1.DATA KIA'!AG50 -> 5 | AO50: =AN50+AM50 -> 6 | AP50: =AO50/E50*100 -> #DIV/0! | AR50: =AT16 -> 1 | AS50: ='1.DATA KIA'!AB50 -> 5 | AT50: =AS50+AR50 -> 6 | AU50: =AT50/D50*100 -> 13.605442 | AW50: =AY16 -> 0 | AX50: ='1.DATA KIA'!AF50 -> 3 | AY50: =AW50+AX50 -> 3 | AZ50: =AY50/(20%*C50)*100 -> 32.467532
A51: 9 | B51: =PETUNJUK!B17 -> Gemulung | C51: ='1.DATA KIA'!C51 -> 53.9 | D51: ='1.DATA KIA'!D51 -> 51.45 | E51: =E17 -> 0 | F51: =H17 -> 4 | G51: ='1.DATA KIA'!F51 -> 5 | H51: =F51+G51 -> 9 | I51: =H51/C51*100 -> 16.697588 | K51: =M17 -> 5 | L51: ='1.DATA KIA'!J51 -> 4 | M51: =K51+L51 -> 9 | N51: =M51/D51*100 -> 17.492711 | P51: =R17 -> 5 | Q51: ='1.DATA KIA'!M51 -> 5 | R51: =P51+Q51 -> 10 | S51: =R51/D51*100 -> 19.436346 | U51: =W17 -> 0 | V51: ='1.DATA KIA'!Y51 -> 0 | W51: =U51+V51 -> 0 | X51: =W51/(20%*C51)*100 -> 0 | Z51: =AB17 -> 0 | AA51: ='1.DATA KIA'!Z51 -> 0 | AB51: =Z51+AA51 -> 0 | AC51: =AB51/(20%*C51)*100 -> 0 | AE51: =AG17 -> 2 | AF51: ='8.ANCTEPADU'!D53+'8.ANCTEPADU'!E53 -> 1 | AG51: =AE51+AF51 -> 3 | AH51: =AG51/C51*100 -> 5.5658627 | AI51: =AK17 -> 0 | AJ51: ='8.ANCTEPADU'!J53 -> 0 | AK51: =AI51+AJ51 -> 0 | AL51: =AK51/C51*100 -> 0 | AM51: =AO17 -> 3 | AN51: ='1.DATA KIA'!AG51 -> 5 | AO51: =AN51+AM51 -> 8 | AP51: =AO51/E51*100 -> #DIV/0! | AR51: =AT17 -> 3 | AS51: ='1.DATA KIA'!AB51 -> 5 | AT51: =AS51+AR51 -> 8 | AU51: =AT51/D51*100 -> 15.549077 | AW51: =AY17 -> 1 | AX51: ='1.DATA KIA'!AF51 -> 1 | AY51: =AW51+AX51 -> 2 | AZ51: =AY51/(20%*C51)*100 -> 18.552876
A52: 10 | B52: =PETUNJUK!B18 -> Pecangaan Wetan | C52: ='1.DATA KIA'!C52 -> 50.6 | D52: ='1.DATA KIA'!D52 -> 48.3 | E52: =E18 -> 0 | F52: =H18 -> 4 | G52: ='1.DATA KIA'!F52 -> 6 | H52: =F52+G52 -> 10 | I52: =H52/C52*100 -> 19.762846 | K52: =M18 -> 3 | L52: ='1.DATA KIA'!J52 -> 4 | M52: =K52+L52 -> 7 | N52: =M52/D52*100 -> 14.492754 | P52: =R18 -> 2 | Q52: ='1.DATA KIA'!M52 -> 3 | R52: =P52+Q52 -> 5 | S52: =R52/D52*100 -> 10.351967 | U52: =W18 -> 1 | V52: ='1.DATA KIA'!Y52 -> 1 | W52: =U52+V52 -> 2 | X52: =W52/(20%*C52)*100 -> 19.762846 | Z52: =AB18 -> 0 | AA52: ='1.DATA KIA'!Z52 -> 0 | AB52: =Z52+AA52 -> 0 | AC52: =AB52/(20%*C52)*100 -> 0 | AE52: =AG18 -> 0 | AF52: ='8.ANCTEPADU'!D54+'8.ANCTEPADU'!E54 -> 0 | AG52: =AE52+AF52 -> 0 | AH52: =AG52/C52*100 -> 0 | AI52: =AK18 -> 2 | AJ52: ='8.ANCTEPADU'!J54 -> 1 | AK52: =AI52+AJ52 -> 3 | AL52: =AK52/C52*100 -> 5.9288538 | AM52: =AO18 -> 7 | AN52: ='1.DATA KIA'!AG52 -> 3 | AO52: =AN52+AM52 -> 10 | AP52: =AO52/E52*100 -> #DIV/0! | AR52: =AT18 -> 7 | AS52: ='1.DATA KIA'!AB52 -> 3 | AT52: =AS52+AR52 -> 10 | AU52: =AT52/D52*100 -> 20.703934 | AW52: =AY18 -> 0 | AX52: ='1.DATA KIA'!AF52 -> 1 | AY52: =AW52+AX52 -> 1 | AZ52: =AY52/(20%*C52)*100 -> 9.8814229
A53: 11 | B53: =PETUNJUK!B19 -> Krasak | C53: ='1.DATA KIA'!C53 -> 117.7 | D53: ='1.DATA KIA'!D53 -> 112.35 | E53: =E19 -> 0 | F53: =H19 -> 15 | G53: ='1.DATA KIA'!F53 -> 10 | H53: =F53+G53 -> 25 | I53: =H53/C53*100 -> 21.240442 | K53: =M19 -> 4 | L53: ='1.DATA KIA'!J53 -> 7 | M53: =K53+L53 -> 11 | N53: =M53/D53*100 -> 9.7908322 | P53: =R19 -> 8 | Q53: ='1.DATA KIA'!M53 -> 10 | R53: =P53+Q53 -> 18 | S53: =R53/D53*100 -> 16.021362 | U53: =W19 -> 1 | V53: ='1.DATA KIA'!Y53 -> 1 | W53: =U53+V53 -> 2 | X53: =W53/(20%*C53)*100 -> 8.4961767 | Z53: =AB19 -> 1 | AA53: ='1.DATA KIA'!Z53 -> 1 | AB53: =Z53+AA53 -> 2 | AC53: =AB53/(20%*C53)*100 -> 8.4961767 | AE53: =AG19 -> 0 | AF53: ='8.ANCTEPADU'!D55+'8.ANCTEPADU'!E55 -> 2 | AG53: =AE53+AF53 -> 2 | AH53: =AG53/C53*100 -> 1.6992353 | AI53: =AK19 -> 1 | AJ53: ='8.ANCTEPADU'!J55 -> 1 | AK53: =AI53+AJ53 -> 2 | AL53: =AK53/C53*100 -> 1.6992353 | AM53: =AO19 -> 8 | AN53: ='1.DATA KIA'!AG53 -> 6 | AO53: =AN53+AM53 -> 14 | AP53: =AO53/E53*100 -> #DIV/0! | AR53: =AT19 -> 8 | AS53: ='1.DATA KIA'!AB53 -> 6 | AT53: =AS53+AR53 -> 14 | AU53: =AT53/D53*100 -> 12.461059 | AW53: =AY19 -> 4 | AX53: ='1.DATA KIA'!AF53 -> 1 | AY53: =AW53+AX53 -> 5 | AZ53: =AY53/(20%*C53)*100 -> 21.240442
A54: 12 | B54: =PETUNJUK!B20 -> Gerdu | C54: ='1.DATA KIA'!C54 -> 23.1 | D54: ='1.DATA KIA'!D54 -> 22.05 | E54: =E20 -> 0 | F54: =H20 -> 1 | G54: ='1.DATA KIA'!F54 -> 1 | H54: =F54+G54 -> 2 | I54: =H54/C54*100 -> 8.6580087 | K54: =M20 -> 3 | L54: ='1.DATA KIA'!J54 -> 2 | M54: =K54+L54 -> 5 | N54: =M54/D54*100 -> 22.675737 | P54: =R20 -> 2 | Q54: ='1.DATA KIA'!M54 -> 1 | R54: =P54+Q54 -> 3 | S54: =R54/D54*100 -> 13.605442 | U54: =W20 -> 0 | V54: ='1.DATA KIA'!Y54 -> 0 | W54: =U54+V54 -> 0 | X54: =W54/(20%*C54)*100 -> 0 | Z54: =AB20 -> 0 | AA54: ='1.DATA KIA'!Z54 -> 1 | AB54: =Z54+AA54 -> 1 | AC54: =AB54/(20%*C54)*100 -> 21.645022 | AE54: =AG20 -> 0 | AF54: ='8.ANCTEPADU'!D56+'8.ANCTEPADU'!E56 -> 0 | AG54: =AE54+AF54 -> 0 | AH54: =AG54/C54*100 -> 0 | AI54: =AK20 -> 0 | AJ54: ='8.ANCTEPADU'!J56 -> 0 | AK54: =AI54+AJ54 -> 0 | AL54: =AK54/C54*100 -> 0 | AM54: =AO20 -> 2 | AN54: ='1.DATA KIA'!AG54 -> 1 | AO54: =AN54+AM54 -> 3 | AP54: =AO54/E54*100 -> #DIV/0! | AR54: =AT20 -> 2 | AS54: ='1.DATA KIA'!AB54 -> 1 | AT54: =AS54+AR54 -> 3 | AU54: =AT54/D54*100 -> 13.605442 | AW54: =AY20 -> 1 | AX54: ='1.DATA KIA'!AF54 -> 0 | AY54: =AW54+AX54 -> 1 | AZ54: =AY54/(20%*C54)*100 -> 21.645022
...

Sheet 3.Komplikasi
A1: LAPORAN KASUS KOMPLIKASI KEBIDANAN
A3: PUSKESMAS | C3: : | N3: : | O3: =PETUNJUK!C5 -> PECANGAAN
A4: BULAN | C4: : | N4: : | O4: JANUARI
A5: NO | B5: DESA | C5: JUMLAH KOMPLIKASI KEBIDANAN | AK5: JUMLAH KOMPLIKASI DALAM KEHAMILAN | AL5: JUMLAH KOMPLIKASI DALAM PERSALINAN | AM5: JUMLAH KOMPLIKASI PASCA PERSALINAN (NIFAS)
C6: Anemia | D6: Perdarahan | E6: PEB / Eklamsi | F6: Infeksi / Febris | G6: Tuberculosis | H6: Malaria | I6: Jantung | J6: DM | K6: Obesitas | L6: Covid-19 (Confirm0 | M6: Abortus | N6: Partus tak maju/ macet/lama | O6: KPD | P6: Retplas / Sisa Plas | Q6: Kelainan Letak | R6: IUFD | S6: APH | T6: Gamelly | U6: Serotinus | V6: parts prematur | W6: penyakit kronis | X6: HPP | Y6: CPD | Z6: Hidramnion | AA6: Premi Tua | AB6: Tali Pusat Menumbung | AC6: Foetal Distres | AD6: Makrosomia | AE6: Hiperemisis | AF6: Riwayat Persalinan Buruk | AG6: PJT/IUGR | AH6: KEK | AI6: Lain - lain | AJ6: JUMLAH
A7: 1 | B7: =PETUNJUK!B9 -> Pecangaan Kulon | E7: 1 | AJ7: =SUM(C7:AI7) -> 1 | AL7: 1
A8: 2 | B8: =PETUNJUK!B10 -> Rengging | M8: 1 | O8: 1 | AJ8: =SUM(C8:AI8) -> 2 | AK8: 1 | AL8: 1
A9: 3 | B9: =PETUNJUK!B11 -> Troso | E9: 1 | O9: 2 | Q9: 1 | AJ9: =SUM(C9:AI9) -> 4 | AK9: 2 | AL9: 2
A10: 4 | B10: =PETUNJUK!B12 -> Ngeling | E10: 1 | N10: 1 | O10: 1 | AJ10: =SUM(C10:AI10) -> 3 | AL10: 3
A11: 5 | B11: =PETUNJUK!B13 -> Lebuawu | AJ11: =SUM(C11:AI11) -> 0
A12: 6 | B12: =PETUNJUK!B14 -> Pulodarat | AJ12: =SUM(C12:AI12) -> 0
A13: 7 | B13: =PETUNJUK!B15 -> Karangrandu | AJ13: =SUM(C13:AI13) -> 0
A14: 8 | B14: =PETUNJUK!B16 -> Kaliombo | AJ14: =SUM(C14:AI14) -> 0
A15: 9 | B15: =PETUNJUK!B17 -> Gemulung | O15: 1 | AJ15: =SUM(C15:AI15) -> 1 | AL15: 1
A16: 10 | B16: =PETUNJUK!B18 -> Pecangaan Wetan | AJ16: =SUM(C16:AI16) -> 0
A17: 11 | B17: =PETUNJUK!B19 -> Krasak | E17: 1 | K17: 1 | O17: 2 | AJ17: =SUM(C17:AI17) -> 4 | AK17: 1 | AL17: 2
A18: 12 | B18: =PETUNJUK!B20 -> Gerdu | O18: 1 | AJ18: =SUM(C18:AI18) -> 1 | AL18: 1
A19: 13 | B19: =PETUNJUK!B21 -> 0
A20: 14 | B20: =PETUNJUK!B22 -> 0
A21: 15 | B21: =PETUNJUK!B23 -> 0
A22: 16 | B22: =PETUNJUK!B24 -> 0
A23: 17 | B23: =PETUNJUK!B25 -> 0
A24: 18 | B24: =PETUNJUK!B26 -> 0
A25: 19 | B25: =PETUNJUK!B27 -> 0
A26: 20 | B26: =PETUNJUK!B28 -> 0
A27: 21 | B27: =PETUNJUK!B29 -> 0
A28: 22 | B28: =PETUNJUK!B30 -> 0
A29: Jumlah | C29: =SUM(C7:C28) -> 0 | D29: =SUM(D7:D28) -> 0 | E29: =SUM(E7:E28) -> 4 | F29: =SUM(F7:F28) -> 0 | G29: =SUM(G7:G28) -> 0 | H29: =SUM(H7:H28) -> 0 | I29: =SUM(I7:I28) -> 0 | J29: =SUM(J7:J28) -> 0 | ... AM29: =SUM(AM7:AM28) -> 0
B31: CATATAN : | N31: Data diambil dari fas.yankes yg menangani (BPM, Pusk, PONED, RB, RS)
A36: LAPORAN KASUS MATERNAL KOMPLIKASI
A38: PUSKESMAS | N38: : | O38: =PETUNJUK!C5 -> PECANGAAN
A39: BULAN | N39: : | O39: ='1.DATA KIA'!C38 -> PEBRUARI
A40: NO | B40: DESA | C40: JUMLAH KOMPLIKASI KEBIDANAN | AK40: JUMLAH KOMPLIKASI DALAM KEHAMILAN | AL40: JUMLAH KOMPLIKASI DALAM PERSALINAN | AM40: JUMLAH KOMPLIKASI PASCA PERSALINAN (NIFAS)
C41: Anemia | D41: Perdarahan | E41: PEB / Eklamsi | F41: Infeksi / Febris | G41: Tuberculosis | H41: Malaria | I41: Jantung | J41: DM | K41: Obesitas | L41: Covid-19 (Confirm0 | M41: Abortus | N41: Partus tak maju/ macet/lama | O41: KPD | P41: Retplas / Sisa Plas | Q41: Kelainan Letak | R41: IUFD | S41: APH | T41: Gamelly | U41: Serotinus | V41: parts prematur | W41: penyakit kronis | X41: HPP | Y41: CPD | Z41: Hidramnion | AA41: Premi Tua | AB41: Tali Pusat Menumbung | AC41: Foetal Distres | AD41: Makrosomia | AE41: Hiperemisis | AF41: Riwayat Persalinan Buruk | AG41: PJT/IUGR | AH41: KEK | AI41: Lain - lain | AJ41: JUMLAH
A42: 1 | B42: =PETUNJUK!B9 -> Pecangaan Kulon | E42: 1 | O42: 2 | AF42: 1 | AJ42: =SUM(C42:AI42) -> 4
A43: 2 | B43: =PETUNJUK!B10 -> Rengging | AJ43: =SUM(C43:AI43) -> 0
A44: 3 | B44: =PETUNJUK!B11 -> Troso | M44: 1 | O44: 1 | AJ44: =SUM(C44:AI44) -> 2
A45: 4 | B45: =PETUNJUK!B12 -> Ngeling | O45: 2 | AI45: 1 | AJ45: =SUM(C45:AI45) -> 3
A46: 5 | B46: =PETUNJUK!B13 -> Lebuawu | AJ46: =SUM(C46:AI46) -> 0
A47: 6 | B47: =PETUNJUK!B14 -> Pulodarat | O47: 1 | U47: 1 | AJ47: =SUM(C47:AI47) -> 2
...

Sheet 4.Komp By Name
A1: LAPORAN KASUS RUJUKAN MATERNAL tahun 2026
A2: PUSKESMAS | D2: =D3 -> 0
A4: NO | B4: BULAN | C4: PUSKESMAS | D4: TANGGAL | E4: NAMA | G4: ALAMAT | H4: UMUR | I4: DIAGNOSA | J4: DIRUJUK KE | K4: KET
E5: Ibu | F5: Suami | H5: (TH)
A6: 1 | B6: Januari | C6: Pecangaan | D6: 46026 | E6: Anis Lailatul F. | F6: M. Sirojul | G6: Ngeling 4/3 | H6: 26 | I6: Partus Tak Maju | J6: RSU RA Kartini Jepara
A7: 2 | D7: 46038 | E7: Al Inayah | F7: Ardi Irawan | G7: Ngeling 2/4 | H7: 25 | I7: KPD | J7: RSU RA Kartini Jepara
A8: 3 | D8: 46046 | E8: Erya Tabita | F8: Krismanu | G8: Ngeling 1/6 | H8: 29 | I8: Hipertensi | J8: RS PKU Muhammadiyah Mayong
A9: 4 | D9: 46024 | E9: Sholikhatun | F9: A. Zakariya | G9: Gerdu 5/1 | H9: 24 | I9: KPD | J9: RSU RA Kartini Jepara
A10: 5 | D10: 46031 | E10: Widhia Putri A. | F10: M. Khoirul Alfin | G10: Gemulung 1/3 | H10: 24 | I10: KPD | J10: RSI Jepara
A11: 6 | D11: 46023 | E11: Aza Fauzun | F11: Mastukin | G11: Karangrandu 6/1 | H11: 34 | I11: Serotinus | J11: RSI Kudus
A12: 7 | D12: 46029 | E12: Elya Septia | F12: Rio Hermawan | G12: Krasak 3/2 | H12: 24 | I12: R. SC, Obesitas | J12: RSU RA Kartini Jepara
A13: 8 | D13: 46034 | E13: Layli Salamah | F13: Deni Miftakhudin | G13: Krasak 4/4 | H13: 28 | I13: KPD | J13: RS PKU Muhammadiyah Mayong
A14: 9 | D14: 46036 | E14: Umi Maghfiroh | F14: Ahmad. Muhlis | G14: Krasak 3/4 | H14: 35 | I14: PEB | J14: RSU RA Kartini Jepara
A15: 10 | D15: 46039 | E15: Sintha Widya | F15: Muhammad | G15: Pulodarat 10/2 | H15: 22 | I15: KPD | J15: PKU Aisiyah Jepara
A16: 11 | D16: 46043 | E16: Sri Martanti | F16: Sutikno | G16: Pecangan Kulon 5/2 | H16: 38 | I16: PEB | J16: RSU RA Kartini Jepara
A17: 12 | D17: 46028 | E17: Venty Zuli Astutik | F17: Khoirul Anam | G17: Troso 9/3 | H17: 36 | I17: PE + KPD | J17: RS PKU Muhammadiyah Mayong
A18: 13 | D18: 46031 | E18: Nur Jannah | F18: Edi Irawan | G18: Troso 6/6 | H18: 29 | I18: KPD | J18: RS PKU Muhammadiyah Mayong
... A48: 8 | D48: 46094 | E48: Farida Dwi A. | F48: Alfan Senibal | G48: Gemulung 1/2 | H48: 18 | I48: Partus Premature | J48: RS PKU Muhammadiyah Mayong
A49: 9 | D49: 46112 | E49: Dewi Umrotus Solikhah | G49: Rengging 20/3 | H49: 27 | I49: Gemelly | J49: RSU RA Kartini Jepara
A50: 10 | D50: 46094 | E50: Sri Rahmawati | F50: Abdullah Khanafi | G50: Pulodarat 7/1 | H50: 32 | I50: R.SC 2x | J50: RS PKU Muhammadiyah Mayong
A51: 11 | D51: 46087 | E51: Nur Hasanah | F51: Alimin | G51: Karangrandu 4/3 | H51: 31 | I51: Partus Tak Maju | J51: RS Graha Husada
A52: 1 | D52: 46118 | E52: Putri Indah | F52: Jahal | G52: Ngeling 1/3 | H52: 21 | I52: KPD | J52: PKU Aisiyah Jepara
A53: 2 | D53: 46121 | E53: Siti Khoiriyah | F53: M. chomfi | G53: Ngeling 6/2 | H53: 28 | I53: KPD | J53: PKU Aisiyah Jepara
A54: 3 | D54: 46131 | E54: Nur Malikah | F54: Nur Sholih | G54: Ngeling 1/2 | H54: 34 | I54: Hipertensi
A55: 4 | D55: 46126 | E55: Subhaweni | F55: Edi P. | G55: Ngeling 4/3 | H55: 31 | I55: Prematur | J55: Graha
A56: 5 | D56: 46121 | E56: Eka Dwi A. | F56: A. Shofiyulah | G56: Kaliombo 3/3 | H56: 26 | I56: KPD | J56: RSI
A57: 6 | D57: 46114 | E57: Diyah Putrei S. | F57: Alfin Anam Ma'ruf | G57: Troso 6/10 | H57: 20 | I57: IUGR + Anemia | J57: RSU RA Kartini Jepara
A58: 7 | D58: 46129 | E58: Noor Fadhilah | F58: Nor Soib | G58: Troso 2/1 | H58: 44 | I58: Plasenta Previa | J58: RSU RA Kartini Jepara
A59: 8 | D59: 46137 | E59: Indira Aprilia W. | F59: Ilham Maulana | G59: Troso 3/7 | H59: 22 | I59: KPD | J59: RS PKU Muhammadiyah Mayong
A60: 9 | D60: 46130 | E60: Sri Aminah | F60: Pasri | G60: Troso 08/10 | H60: 40 | I60: Abonrtus inkomplet | J60: RSB Resttu Ibu
A61: 10 | D61: 46140 | E61: Sulistyowati | F61: Setyo Yosep | G61: Troso 9/6 | H61: 40 | I61: Abortus Iminens | J61: RSU RA Kartini Jepara
A62: 11 | D62: 46115 | E62: Arum Laras R. | F62: Ferdian | G62: Pecangaan Kulon 3/1 | H62: 27 | I62: Partus Tak Maju | J62: Klinik Kumalasiwi Kudus
A63: 12 | D63: 46129 | E63: Surini | F63: Subagio | G63: Pecangaan Kulon 3/5 | H63: 42 | I63: Riwayat SC + PE | J63: RS PKU Muhammadiyah Mayong
A64: 13 | D64: 46134 | E64: Leni Sintia | F64: Suraji | G64: Pecangaan Kulon 4/7 | H64: 26 | I64: KPD | J64: RSI Sunan Kudus
A65: 14 | D65: 46132 | E65: Kustriana | F65: A. Aslon | G65: Pecangaan Kulon 2/7 | H65: 26 | I65: Abortus | J65: RS PKU Muhammadiyah Mayong
A66: 15 | D66: 46132 | E66: Mia Romadani | F66: M. Syahril | G66: Lebuawu 7/4 | H66: 24 | I66: PEB + Obesitas | J66: RSU RA Kartini Jepara
... A74: 23 | D74: 46142 | E74: Eva Amilia | F74: Pandu Dwi Jayanto | G74: Rengging 3/1 | H74: 26 | I74: Partus Tak Maju | J74: RSU RA Kartini Jepara

Sheet 5.Mati Maternal
A1: DATA REKAP BY NAME BY ADDRESS TAHUN 2026 JEPARA
A2: PUSKESMAS
A4: NO | B4: NAMA IBU | C4: NAMA SUAMI | D4: ALAMAT | E4: WILAYAH PUSKESMAS | F4: TANGGAL KEMATIAN | G4: USIA IBU | J4: PENDIDIKAN IBU | O4: G P A | P4: PARITAS | S4: FREK ANC | U4: JARAK ANAK | V4: JARAK KEHAMILAN TERAKHIR | X4: SEBAB KEMATIAN | AH4: MENINGGAL SAAT | AK4: PENOLONG PERSALINAN | AN4: TEMPAT PERSALINAN | AT4: RS | AU4: TEMPAT KEMATIAN | BA4: MATI DI RS | BC4: CARA PERSALINAN | BF4: RIWAYAT VAKSINASI COVID | BJ4: Keterangan
G5: < 20 TH | H5: 20 - 30 TH | I5: > 30 TH | J5: <SD | K5: SD | L5: SMP | M5: SMA | N5: PT | P5: PRIMI | Q5: MULTI | R5: GRANDE | S5: < 6 KALI | T5: > 6 KALI | V5: < 2 TH | W5: > 2 TH | X5: HIPERTENSI / EKLAMSI | Y5: PERDARAHAN | Z5: INFEKSI MASA NIFAS | AA5: ABORTUS | AB5: JANTUNG | AC5: GG sistem metabolik | AD5: GANGGUAN DARAH | AE5: KEHAMILAN EKTOPIK | AF5: COVID | AG5: LAIN2 (sebutkan) | AH5: HAMIL | AI5: BERSALIN NIFAS | AJ5: NIFAS | AK5: DUKUN | AL5: BIDAN | AM5: DOKTER | AN5: RUMAH | AO5: JALAN | AP5: BPM | AQ5: RB | AR5: PUSK | AS5: RS | AU5: RUMAH | AV5: JALAN | AW5: BPM | AX5: RB | AY5: PUSK | AZ5: RS | BA5: < 48 JAM | BB5: > 48 JAM | BC5: NORMAL | BD5: VE/Forcep | BE5: SC | BF5: TDK VAKSIN | BG5: V 1 | BH5: V2 | BI5: V3
A25: TOTAL | G25: =COUNTA(G6:G24) -> 0 | H25: =COUNTA(H6:H24) -> 0 | I25: =COUNTA(I6:I24) -> 0 | J25: =COUNTA(J6:J24) -> 0 | K25: =COUNTA(K6:K24) -> 0 | L25: =COUNTA(L6:L24) -> 0 | M25: =COUNTA(M6:M24) -> 0 | N25: =COUNTA(N6:N24) -> 0 | ... Z25: =COUNTA(Z6:Z24) -> 0 | AB25: =COUNTA(AB6:AB24) -> 0 | AC25: =COUNTA(AC6:AC24) -> 0 | AF25: =COUNTA(AF6:AF24) -> 0 | AG25: =COUNTA(AG6:AG24) -> 0 | AH25: =COUNTA(AH6:AH24) -> 0 | AI25: =COUNTA(AI6:AI24) -> 0 | AJ25: =COUNTA(AJ6:AJ24) -> 0 | AK25: =COUNTA(AK6:AK24) -> 0 | AL25: =COUNTA(AL6:AL24) -> 0 | AM25: =COUNTA(AM6:AM24) -> 0 | ... AS25: =COUNTA(AS6:AS24) -> 0 | AU25: =COUNTA(AU6:AU24) -> 0 | AV25: =COUNTA(AV6:AV24) -> 0 | AW25: =COUNTA(AW6:AW24) -> 0 | AX25: =COUNTA(AX6:AX24) -> 0 | AY25: =COUNTA(AY6:AY24) -> 0 | AZ25: =COUNTA(AZ6:AZ24) -> 0 | BA25: =COUNTA(BA6:BA24) -> 0 | BB25: =COUNTA(BB6:BB24) -> 0 | ... BI25: =COUNTA(BI6:BI24) -> 0

Sheet 6.P4K
C1: LAPORAN HASIL PELAKSANAAN P4K
C2: PUSKESMAS : | E2: =PETUNJUK!C5 -> PECANGAAN
C3: BULAN : | E3: ='1.DATA KIA'!C4 -> JANUARI | V3: Lamp. 1 | AO3: Lamp. 2
A5: NO | B5: DESA | C5: SASARAN BUMIL | D5: BUMIL TERPASANG STIKER | H5: BUMIL TERPASANG STIKER BERSALIN | L5: HASIL AKHIR AMANAT PERSALINAN | Z5: HASIL AKHIR PELAYANAN AMANAT PERSALINAN
D6: Bln Lalu | E6: Bln ini | F6: ABS | G6: % | H6: Bln Lalu | I6: Bln ini | J6: ABS | K6: % | L6: FREK ANC | N6: PAHAM TANDA BAHAYA KEHAMILAN DAN PERSALINAN | P6: PENOLONG PERSALINAN | S6: TEMPAT BERSALIN | Z6: PENDAMPINGAN PERSALINAN | AC6: KESIAPAN TRANSPORTASI | AE6: DONOR DARAH | AG6: KB YANG DIGUNAKAN | AM6: KEADAAN
L7: > 4 KL | M7: < 4 KL | N7: TAHU | O7: TIDAK | P7: BIDAN | Q7: DUKUN | R7: DOKTER | S7: PUSK | T7: PKD | U7: RS | V7: RB | W7: RUMAH | Z7: KELUARGA | AA7: DUKUN | AB7: BIDAN | AC7: KLG | AD7: DESA | AE7: KLG | AF7: DESA | AG7: BLM | AH7: KOND | AI7: SUNT | AJ7: PIL | AK7: IMPL | AL7: LAIN2 | AM7: IBU | AO7: BAYI
W8: BIDAN | X8: SENDIRI | AM8: HIDUP | AN8: MATI | AO8: HIDUP | AP8: MATI
A9: 1 | B9: =PETUNJUK!B9 -> Pecangaan Kulon | C9: ='1.DATA KIA'!C9 -> 101.2 | D9: 0 | E9: ='1.DATA KIA'!F9 -> 7 | F9: =D9+E9 -> 7 | G9: =F9/C9*100 -> 6.916996 | H9: 0 | I9: ='1.DATA KIA'!AB9+'1.DATA KIA'!AE9 -> 10 | J9: =H9+I9 -> 10 | K9: =J9/C9*100 -> 9.8814229 | L9: =I9 -> 10 | N9: =I9 -> 10 | P9: 7 | R9: =I9-P9 -> 3 | S9: 1 | U9: 3 | W9: =I9-(S9+T9+U9+V9) -> 6 | Z9: =S9+T9+W9+X9 -> 7 | AB9: =I9-Z9 -> 3 | AC9: =I9 -> 10 | AE9: =I9 -> 10 | AG9: =I9-(AH9+AI9+AJ9+AK9+AL9) -> 3 | AI9: 4 | AJ9: 1 | AK9: 1 | AL9: 1 | AM9: =I9 -> 10 | AO9: =I9 -> 10
A10: 2 | B10: =PETUNJUK!B10 -> Rengging | C10: ='1.DATA KIA'!C10 -> 111.1 | D10: 0 | E10: ='1.DATA KIA'!F10 -> 23 | F10: =D10+E10 -> 23 | G10: =F10/C10*100 -> 20.70207 | H10: 0 | I10: ='1.DATA KIA'!AB10+'1.DATA KIA'!AE10 -> 14 | J10: =H10+I10 -> 14 | K10: =J10/C10*100 -> 12.60126 | L10: =I10 -> 14 | N10: =I10 -> 14 | P10: 7 | R10: =I10-P10 -> 7 | S10: 1 | U10: 9 | W10: =I10-(S10+T10+U10+V10) -> 4 | Z10: =S10+T10+W10+X10 -> 5 | AB10: =I10-Z10 -> 9 | AC10: =I10 -> 14 | AE10: =I10 -> 14 | AG10: =I10-(AH10+AI10+AJ10+AK10+AL10) -> 0 | AI10: 13 | AL10: 1 | AM10: =I10 -> 14 | AO10: =I10 -> 14
A11: 3 | B11: =PETUNJUK!B11 -> Troso | C11: ='1.DATA KIA'!C11 -> 205.7 | D11: 0 | E11: ='1.DATA KIA'!F11 -> 18 | F11: =D11+E11 -> 18 | G11: =F11/C11*100 -> 8.7506077 | H11: 0 | I11: ='1.DATA KIA'!AB11+'1.DATA KIA'!AE11 -> 17 | J11: =H11+I11 -> 17 | K11: =J11/C11*100 -> 8.2644628 | L11: =I11 -> 17 | N11: =I11 -> 17 | P11: 10 | R11: =I11-P11 -> 7 | S11: 3 | U11: 6 | W11: =I11-(S11+T11+U11+V11) -> 8 | Z11: =S11+T11+W11+X11 -> 11 | AB11: =I11-Z11 -> 6 | AC11: =I11 -> 17 | AE11: =I11 -> 17 | AG11: =I11-(AH11+AI11+AJ11+AK11+AL11) -> 0 | AI11: 17 | AM11: =I11 -> 17 | AO11: =I11 -> 17
A12: 4 | B12: =PETUNJUK!B12 -> Ngeling | C12: ='1.DATA KIA'!C12 -> 95.7 | D12: 0 | E12: ='1.DATA KIA'!F12 -> 7 | F12: =D12+E12 -> 7 | G12: =F12/C12*100 -> 7.3145246 | H12: 0 | I12: ='1.DATA KIA'!AB12+'1.DATA KIA'!AE12 -> 9 | J12: =H12+I12 -> 9 | K12: =J12/C12*100 -> 9.4043887 | L12: =I12 -> 9 | N12: =I12 -> 9 | P12: 6 | R12: =I12-P12 -> 3 | S12: 0 | U12: 3 | W12: =I12-(S12+T12+U12+V12) -> 6 | Z12: =S12+T12+W12+X12 -> 6 | AB12: =I12-Z12 -> 3 | AC12: =I12 -> 9 | AE12: =I12 -> 9 | AG12: =I12-(AH12+AI12+AJ12+AK12+AL12) -> 0 | AI12: 9 | AM12: =I12 -> 9 | AO12: =I12 -> 9
A13: 5 | B13: =PETUNJUK!B13 -> Lebuawu | C13: ='1.DATA KIA'!C13 -> 85.8 | D13: 0 | E13: ='1.DATA KIA'!F13 -> 9 | F13: =D13+E13 -> 9 | G13: =F13/C13*100 -> 10.48951 | H13: 0 | I13: ='1.DATA KIA'!AB13+'1.DATA KIA'!AE13 -> 7 | J13: =H13+I13 -> 7 | K13: =J13/C13*100 -> 8.1585082 | L13: =I13 -> 7 | N13: =I13 -> 7 | P13: 5 | R13: =I13-P13 -> 2 | S13: 3 | U13: 2 | W13: =I13-(S13+T13+U13+V13) -> 2 | Z13: =S13+T13+W13+X13 -> 5 | AB13: =I13-Z13 -> 2 | AC13: =I13 -> 7 | AE13: =I13 -> 7 | AG13: =I13-(AH13+AI13+AJ13+AK13+AL13) -> 0 | AI13: 5 | AL13: 2 | AM13: =I13 -> 7 | AO13: =I13 -> 7
